Workbook

Sheet 총괄
A1: 46043
A3: 회사 | B3: NO. | C3: 구분 | D3: 내용 | E3: 분양가 | F3: 보증금 | G3: 월세 | I3: 상세보기 | J3: 활용방안
A4: 트리플에이치 | B4: 1 | C4: 상가 | D4: =COUNTA('향남 에듀스퀘어'!A7:A12,'향남 에듀스퀘어'!A14:A19,'향남 에듀스퀘어'!A21:A28,'향남 에듀스퀘어'!A30:A36)-COUNTIF('향남 에듀스퀘어'!B7:B36,"분양") -> 향남 에듀스퀘어 미분양 26세대 | E4: =+'향남 에듀스퀘어'!T38 -> 7,240,956,040
D5: =COUNTIF('향남 에듀스퀘어'!B7:B36,"분양") -> 향남 에듀스퀘어 분양계약 0세대 | E5: =+'향남 에듀스퀘어'!T39 -> 0
D6: =+COUNTIF('향남 에듀스퀘어'!AL7:AL36,"선임대") -> 향남 에듀스퀘어 임대 5세대 | F6: =+'향남 에듀스퀘어'!AS38 -> 145,000,000 | G6: =+'향남 에듀스퀘어'!AT38 -> 9,100,000
B7: =B4+1 -> 2 | C7: 토지 | D7: 향남 단독, 상가주택부지 | E7: =+'향남 단독부지'!H24 -> 6,516,576,925
B8: =B7+1 -> 3 | C8: 토지 | D8: 보성리 2538 | E8: =+'보성리'!F9 -> 49,696,837,786 | H8: 토지및 관련 부대비용 지급완료 합계액
B9: =B8+1 -> 4 | C9: 상가 | D9: 파주 리버팰리스 단지 내 상가(교회_1201~1203호) | E9: =+'파주상가'!F6 -> 462,000,000
B10: =B9+1 -> 5 | C10: 상가 | D10: 파주 리버팰리스 단지 내 상가(1204~1207호) | E10: =+'파주상가'!F7 -> 314,036,361
B11: =B10+1 -> 6 | C11: 토지 | D11: 당동리 515-19외 2필지 | E11: =+'파주당동리'!F9 -> 526,382,800
B12: =B11+1 -> 7 | C12: 아파트 | D12: 향남 에일린의뜰 402동 1702호 | E12: ='[1]향남 에일린의 뜰'!E6 -> #REF! | F12: =+'향남에일린의뜰'!G6 -> 20,000,000 | G12: =+'향남에일린의뜰'!H6 -> 1,200,000
B13: =B12+1 -> 8 | C13: 아파트 | D13: 파주 리버팰리스 (114동 1405호_41평) | E13: =+'파주리버팰리스'!E6 -> 286,150,000 | H13: 무상임대중
B14: 합계 | E14: =SUM(E4:E13) -> #REF! | F14: =SUM(F4:F13) -> 165,000,000 | G14: =SUM(G4:G13) -> 10,300,000
A15: 한양글로벌디앤이 | B15: 1 | C15: 생숙 | D15: 의정부역 한양수자인파크뷰 5개 호실 | E15: =+'의정부한양파크뷰'!F53 -> 728,000,000 | H15: 26/2/2 용도변경 접수, 숙박업 예비신고 취소
B16: =B15+1 -> 2 | C16: 도생 | D16: 의정부역 한양수자인파크뷰 40개 호실 | E16: =+'의정부한양파크뷰'!F54 -> 4,837,000,000 | F16: =+'의정부한양파크뷰'!J56 -> 405,000,000 | G16: =+'의정부한양파크뷰'!J54 -> 17,630,000
B17: 3 | C17: 상가 | D17: 의정부역 한양수자인파크뷰 B1호 | E17: =+'의정부상가'!F5 -> 1,500,000,000 | F17: =+'의정부상가'!G5 -> 50,000,000 | G17: =+'의정부상가'!H5 -> 5,500,000
B18: 4 | C18: 상가 | D18: 의정부역 한양수자인파크뷰 B2호 | E18: =+'의정부상가'!F6 -> 300,000,000
B19: 5 | C19: 토지 | D19: 의정부동 240-142(45.37평) | E19: =+'의정부토지'!F6 -> 1,437,175,541
B20: 합계 | E20: =SUM(E15:E19) -> 8,802,175,541 | F20: =SUM(F15:F19) -> 455,000,000 | G20: =SUM(G15:G19) -> 23,130,000
A21: 앤유 | B21: 1 | C21: 토지 | D21: 낙하리301-7외4필지 | E21: =+'낙하리'!H24 -> 5,039,203,000
B22: =B21+1 -> 2 | C22: 창고 | D22: 낙하리 301-7 가동 | E22: =+'낙하리'!H11 -> 74,646,000
B23: =B22+1 -> 3 | C23: 창고 | D23: 낙하리 301-7 나동-1 | E23: =+'낙하리'!H12/2 -> 37,323,000
B24: =B23+1 -> 4 | C24: 창고 | D24: 낙하리 301-7 나동-2 | E24: =+'낙하리'!H12/2 -> 37,323,000 | F24: 30000000 | G24: 2300000
B25: =B24+1 -> 5 | C25: 창고 | D25: 낙하리 301-7 다, 라동 | E25: =+'낙하리'!H13+'낙하리'!H14 -> 149,292,000
B26: =B25+1 -> 6 | C26: 공장 | D26: 낙하리 301-9 | E26: =+'낙하리'!H22 -> 525,510,204
B27: 합계 | E27: =SUM(E21:E26) -> 5,863,297,204 | F27: =SUM(F21:F26) -> 30,000,000 | G27: =SUM(G21:G26) -> 2,300,000
A28: 쓰리아이 | B28: 1 | C28: 태양광 | D28: 태양광 매출
B29: 합계
A30: 선엔젤스 | B30: 1 | C30: 상가 | D30: 고척동 지하상가 | E30: =+'고척동상가'!F6 -> 1,500,000,000
B31: 합계 | E31: =SUM(E30) -> 1,500,000,000 | F31: =SUM(F30) -> - | G31: =SUM(G30) -> -
A32: 전체합계 | E32: =E14+E20+E27+E29+E31 -> #REF! | F32: =F14+F20+F27+F29+F31 -> 650,000,000 | G32: =G14+G20+G27+G29+G31 -> 35,730,000

Sheet 파주당동리
A1: 당동리 515-19외 2필지
A4: 상세현황
A5: 구분 | B5: 순번 | C5: 주소 | D5: 면적(㎡) | E5: 면적(평) | F5: 자산가치 | G5: 세금 | H5: 2024년 공시지가 | I5: 매각 계획
A6: 토지 | B6: 1 | C6: 당동리 515-19 | D6: 826 | E6: =D6/3.3058 -> 249.86평 | F6: 310823800 | G6: 14928729 | H6: =376300*D6 -> 310,823,800
A7: 토지 | B7: 2 | C7: 당동리 172-18 | D7: 2722 | E7: =D7/3.3058 -> 823.4평 | F7: 151615400 | H7: =55700*D7 -> 151,615,400
A8: 토지 | B8: 3 | C8: 당동리 173-5 | D8: 1148 | E8: =D8/3.3058 -> 347.27평 | F8: 63943600 | H8: =55700*D8 -> 63,943,600
E9: 합계 | F9: =SUM(F6:F8) -> 526,382,800
F10: **공시지가 기준

Sheet 향남에일린의뜰
A1: 향남 에일린의 뜰 402동 1702호
A4: 상세현황
A5: 구분 | B5: 순번 | C5: 면적(㎡) | D5: 면적(평) | E5: 기존 매입가 (분양가) | F5: 현상태 | G5: 보증금 | H5: 월세 | I5: 소유권이전등기비용 (취득세 등 포함) | J5: 2024년재산세 | K5: 매각희망가 | L5: 수익률 (매각예정가 세전) | M5: 수익률(세후) | N5: 공시지가 | O5: 계약기간 | P5: 매각 계획
A6: 아파트 | B6: 1 | C6: =D6*3.3 -> 112.2 | D6: 34 | E6: =460000000+I6 -> 518,828,310 | F6: 월세임대중 | G6: 20000000 | H6: 1200000 | I6: 58828310 | J6: =228940*2 -> 457,880 | K6: 480000000 | L6: =(K6-E6)/(E6-G6) -> -8% | M6: =(K6-E6)/((E6+I6)-G6) -> -7% | N6: 248000000 | O6: 25.08.31~27.08.31 | P6: 현재 전세올려받을수 없음 (2.5억 시세) 매매시세가 현저히 떨어진 상황이어서, 기다렸다 매각
E7: *매매대+소유권이전등기비용포함

Sheet 파주리버팰리스
A1: 파주 리버팰리스 114동 1405호
A4: 상세현황
A5: 구분 | B5: 순번 | C5: 면적(㎡) | D5: 면적(평) | E5: 기존 매입가 (분양가) | F5: 현상태 | G5: 보증금 | H5: 세금 | I5: 매각예정가 | J5: 수익률 (매각예정가 세전) | K5: 세금 | L5: 수익률(세후) | M5: 공시가격 | N5: 계약기간 | O5: 매각 계획
A6: 리버팰리스 114동 1405호 | B6: 2 | C6: =D6*3.3 -> 155.1 | D6: 47 | E6: 286150000 | F6: 미분양 | H6: 406863 | K6: =436600+3631800+58828310 -> 62,896,710 | L6: =J6*12-K6/E6-G6*100 -> 0 | M6: 203000000 | O6: 없음

Sheet 고척동상가
A1: 고척동 지하상가
A4: 상세현황
A5: 구분 | B5: 순번 | C5: 호수 | D5: 면적(㎡) | E5: 면적(평) | F5: 기존 매입가 (분양가) | G5: 현상태 | H5: 보증금 | I5: 월세 | J5: 수익률
A6: 상가 | B6: 1 | C6: 지하30호 | E6: 254 | F6: 1500000000 | G6: 트리플에이치 | H6: 30000000 | I6: 5000000 | J6: =I6*12/(F6-H6) -> 4% | K6: (vat 제외)
G7: 25.11.10 | J7: 0

Sheet 의정부한양파크뷰1
M7: 현재 공실 상태

Sheet 의정부한양파크뷰2

Sheet 의정부한양파크뷰
A5: 상세현황
A6: 구분 | B6: 순번 | C6: 호수 | D6: 공급면적(㎡) | E6: 면적(평) | F6: 분양가 | G6: 2024공시가격 | H6: 현상태 | I6: 보증금 | J6: 월세(vat포함) | K6: 수익률(세전) | L6: 세금 | M6: 수익률(세후) | N6: 임차기간 | O6: 계약 만료일 | P6: 미납현황 | Q6: 계약잔여일수 | R6: 호수 | S6: 임차인 | T6: 전화번호 | U6: 임차신고 | V6: 비고 | W6: 메모 | X6: 대출 담보액 | Y6: 매물 동향 | Z6: 최근 실거래 | AA6: 물건 종합
A7: 생활형 숙박시설 | B7: 1 | C7: 301 | D7: 49.73 | E7: =D7/3.3058 -> 15.04 | F7: 193000000 | H7: 월세 | I7: 10000000 | J7: 700000 | K7: =J7*12/(F7-I7) -> 4.59% | L7: 233924 | M7: =(J7*12-L7)/(F7-I7) -> 4.46% | P7: 0 | Q7: =(O7-TODAY()) -> -46160일 | R7: 301 | X7: 2990000000 | Y7: 생숙 1호라인 매물 없음 | Z7: 생활형숙박시설 최근 1년간 실거래 없음 | AA7: ① 생활형 숙박시시설 규제로 인해 거래가 이뤄지지 않고 있음 ② 용도변경 불가, 숙박업으로 전환 후 매매 진행 ③ 숙박업 전환시 최소 30세대 이상 동의 후 함께 진행
B8: 2 | C8: 303 | D8: 32.24 | E8: =D8/3.3058 -> 9.75 | F8: 133000000 | H8: 월세 | I8: 5000000 | J8: 550000 | K8: =J8*12/(F8-I8) -> 5.16% | L8: 145178 | P8: 0 | Q8: =O8-TODAY() -> -46160일 | R8: 303 | Y8: 생활형 숙박시설 매물: ① 5층 / 매매가 1억 / 분양가 대비 -3,600만원
B9: 3 | C9: 304 | D9: 32.24 | E9: =D9/3.3058 -> 9.75 | F9: 133000000 | H9: 월세 | I9: 5000000 | J9: 550000 | K9: =J9*12/(F9-I9) -> 5.16% | L9: 145178 | P9: 0 | Q9: =O9-TODAY() -> -46160일 | R9: 304
B10: 4 | C10: 313 | D10: 32.24 | E10: =D10/3.3058 -> 9.75 | F10: 133000000 | H10: 월세 | I10: 5000000 | J10: 500000 | K10: =J10*12/(F10-I10) -> 4.69% | L10: 149047 | M10: =(J10*12-L10)/(F10-I10) -> 4.57% | P10: 0 | Q10: =O10-TODAY() -> -46160일 | R10: 313 | W10: 010-5423-1907(딸: 전예나_실거주자), 명도소송진행중
B11: 5 | C11: 503 | D11: 32.24 | E11: =D11/3.3058 -> 9.75 | F11: 136000000 | H11: 월세 | I11: 5000000 | J11: 550000 | K11: =J11*12/(F11-I11) -> 5.04% | L11: 145178 | N11: 2024.05.08~2026.05.07 | O11: 46149 | P11: 0 | Q11: =O11-TODAY() -> -11일 | R11: 503 | S11: 최보연 | T11: 010-5447-8532 | U11: O | W11: 010-4500-8532 (어머니)
A12: 도시형 생활주택 | B12: 6 | C12: 713 | D12: 26.15 | E12: =D12/3.3058 -> 7.91 | F12: 99000000 | H12: 월세 | I12: 5000000 | J12: 420000 | K12: =J12*12/(F12-I12) -> 5.36% | L12: 86451 | M12: =(J12*12-L12)/(F12-I12) -> 5.27% | N12: 2025.08.16-2026.08.15 | O12: 46249 | P12: 0 | Q12: =O12-TODAY() -> 89일 | R12: 713 | S12: 곽민채 | Y12: <매매> 도시형 생활주택 매물: * 현재 매매 물건 16개 (1호 라인 없음) ① 최저가 매물: 15층 / 매매가 8,000만원 / 분양가 대비 약 -2,800만원 ② 최고가 매물: 21층 / 매매가 1.5억원 / 분양가 대비 약 +500만원 ③ 평균 매물가: 전층 / 매매가 9,000만원 / 분양가 대비 약 -1,500만원 * 현재 전세 물건 3개 (1호 라인 없음) ① 최저가 매물: 저층 / 전세가 8,500만원 / 전세가율 약 83% ② 최고가 매물: 14층 / 전세가 9,500만원 / 전세가율 약 87% | Z12: 도시형 생활주택 2023년 매매 실거래 * 2023년 매매 실거래 9건 ① 3월: 1건 / 9,000만원 / 24층 / 분양가 대비 약 -2,250만원 ② 4월: 1건 / 8,500만원 / 15층 / 분양가 대비 약 -2,300만원 ③ 5월: 2건 / 1억 1,650만원 / 24층 / 분양가 동일 1억 950만원 / 18층 / 분양가 동일 ④ 9월: 3건 / 8,000만원 / 15층 / 분양가 대비 약 -2,800만원 9,000만원 / 22층 / 분양가 대비 약 -2,100만원 9,500만원 / 8층 / 분양가 대비 약 -700만원 ⑤ 10월: 1건 / 8,000만원 / 22층 / 분양가 대비 약 -3,100만원 ② 11월: 1건 / 8,000만원 / 24층 / 분양가 대비 약 -3,250만원 | AA12: ① 주택수 산정 / 청약시만 무주택 인정 ② 의정부역 주변 비슷한 매물의 시장가격도 동반하락해서 당분간은 현 가격 유지 예상 ③ 고금리로 인해 수익률 저하 ④ 당현장 수익률 계산 1) 한양파크뷰 평균 수익률 4.75% 2) 23억 담보대출 / 5.88% 3) 이자 제외 수익률 = 2.08% 4) 연간 수익: 104,880,000 ⑤ 인근 비슷한 매물 월세: 40~45만원 사이 / 당현장 월세 올리기 어려움 ⑥당현장 평균 매매가 9,000만원으로 분양가 대비 약 -2,000만원 이상 할인 + 수수료 지급해야 매매 가능 ⑦ 당장 판매보다, GTX 개통(23년말 착공, 28년말 완공예정) 후 실수요 증가 및 부동산시장 변화시기를 기다려 판매하는 전략이 유리할 것으로 예상
B13: 7 | C13: 802 | D13: 26.15 | E13: =D13/3.3058 -> 7.91 | F13: 102000000 | H13: 월세 | I13: 5000000 | J13: 420000 | K13: =J13*12/(F13-I13) -> 5.20% | L13: 86451 | N13: 2025.08.26-2026.08.25 | O13: 46259 | P13: 0 | Q13: =O13-TODAY() -> 99일 | R13: 802 | S13: 김효정 | U13: O
B14: 8 | C14: 808 | D14: 26.15 | E14: =D14/3.3058 -> 7.91 | F14: 102000000 | H14: 월세 | I14: 5000000 | J14: 420000 | K14: =J14*12/(F14-I14) -> 5.20% | L14: 86451 | N14: 2025.01.09-2026.01.08 | O14: 46030 | P14: 0 | Q14: =O14-TODAY() -> -130일 | R14: 808 | S14: 홍채민 | T14: 010-4690-1656 | U14: O
B15: 9 | C15: 901 | D15: 39.7 | E15: =D15/3.3058 -> 12.01 | F15: 165000000 | H15: 월세 | I15: 10000000 | J15: 650000 | K15: =J15*12/(F15-I15) -> 5.03% | L15: 127408 | N15: 2023.03.21-2026.03.20 | O15: 46101 | P15: 1300000 | Q15: =O15-TODAY() -> -59일 | R15: 901 | S15: 박성민 | T15: 010-8959-7072 | U15: O
B16: 10 | C16: 1001 | D16: 39.7 | E16: =D16/3.3058 -> 12.01 | F16: 165000000 | H16: 월세 | I16: 10000000 | J16: 650000 | K16: =J16*12/(F16-I16) -> 5.03% | L16: 130840 | N16: 2024.07.08-2026.07.07 | O16: 46210 | P16: 0 | Q16: =O16-TODAY() -> 50일 | R16: 1001 | S16: 우효경 | T16: 010-9239-4336 | U16: O
B17: 11 | C17: 1201 | D17: 39.7 | E17: =D17/3.3058 -> 12.01 | F17: 166500000 | H17: 월세 | I17: 10000000 | J17: 650000 | K17: =J17*12/(F17-I17) -> 4.98% | L17: 134272 | N17: 2024.04.28-2026.04.27 | O17: 46139 | P17: 0 | Q17: =O17-TODAY() -> -21일 | R17: 1201 | S17: 정다영 | T17: 010-2621-1086 | U17: O
B18: 12 | C18: 1301 | D18: 39.7 | E18: =D18/3.3058 -> 12.01 | F18: 166500000 | H18: 월세 | I18: 10000000 | J18: 600000 | K18: =J18*12/(F18-I18) -> 4.60% | L18: 134272 | N18: 2025.10.01-2026.09.30 | O18: 46295 | P18: 0 | Q18: =O18-TODAY() -> 135일 | R18: 1301 | S18: 이수연 | U18: O | W18: 실거주자(채원국): 010-9199-3390
B19: 13 | C19: 1501 | D19: 39.7 | E19: =D19/3.3058 -> 12.01 | F19: 168000000 | H19: 월세 | I19: 10000000 | J19: 600000 | K19: =J19*12/(F19-I19) -> 4.56% | L19: 134272 | N19: 2025.02.07-2026.02.06 | O19: 46059 | P19: 0 | Q19: =O19-TODAY() -> -101일 | R19: 1501 | S19: 박민진 | T19: 010-2751-6451 | U19: O
B20: 14 | C20: 1601 | D20: 39.7 | E20: =D20/3.3058 -> 12.01 | F20: 168000000 | H20: 월세 | I20: 10000000 | J20: 650000 | K20: =J20*12/(F20-I20) -> 4.94% | L20: 134272 | N20: 2024.08.15-2026.08.14 | O20: 46248 | P20: 0 | Q20: =O20-TODAY() -> 88일 | R20: 1601 | S20: 함지윤 | T20: 010-9452-3505 | U20: O
B21: 15 | C21: 1702 | D21: 26.15 | E21: =D21/3.3058 -> 7.91 | F21: 109500000 | H21: 월세 | I21: 5000000 | J21: 420000 | K21: =J21*12/(F21-I21) -> 4.82% | L21: 89727 | M21: =(J21*12-L21)/(F21-I21) -> 4.74% | N21: 2024.12.02-2025.12.01 | O21: 45992 | P21: 0 | Q21: =O21-TODAY() -> -168일 | R21: 1702 | S21: 정서윤 | T21: 010-5653-0906 | U21: O
B22: 16 | C22: 1703 | D22: 26.15 | E22: =D22/3.3058 -> 7.91 | F22: 109500000 | H22: 월세 | I22: 5000000 | J22: 400000 | K22: =J22*12/(F22-I22) -> 4.59% | L22: 89727 | N22: 2023.06.24-2026.06.23 | O22: 46196 | P22: 0 | Q22: =O22-TODAY() -> 36일 | R22: 1703 | S22: 정시아 | T22: 010-7151-6377 | U22: O
B23: 17 | C23: 1714 | D23: 26.15 | E23: =D23/3.3058 -> 7.91 | F23: 113500000 | H23: 월세 | I23: 5000000 | J23: 450000 | K23: =J23*12/(F23-I23) -> 4.98% | L23: 91287 | N23: 2024.04.30-2026.04.29 | O23: 46141 | P23: 0 | Q23: =O23-TODAY() -> -19일 | R23: 1714 | S23: 이혜진 | T23: 010-3292-0351 | U23: O
B24: 18 | C24: 1718 | D24: 26.15 | E24: =D24/3.3058 -> 7.91 | F24: 113500000 | H24: 전세 | I24: 90000000 | K24: =I24*3.5%/F24 -> 2.78% | L24: 91287 | M24: =(I24*3.5%-L24)/F24 -> 2.69% | N24: 2023.04.19-2027.04.18 | O24: 46495 | P24: 0 | Q24: =O24-TODAY() -> 335일 | R24: 1718 | S24: 경기지방중소벤처기업청 | T24: 031-201-6916 | U24: X | W24: 거래신고법 시행 이전 계약건/ 담당자: 010-9616-1148 / 실거주자: 010-9822-8322
B25: 19 | C25: 1719 | D25: 26.15 | E25: =D25/3.3058 -> 7.91 | F25: 113500000 | H25: 월세 | I25: 5000000 | J25: 450000 | K25: =J25*12/(F25-I25) -> 4.98% | L25: 91287 | M25: =(J25*12-L25)/(F25-I25) -> 4.89% | N25: 2025.08.02-2026.08.01 | O25: 46235 | P25: 0 | Q25: =O25-TODAY() -> 75일 | R25: 1719 | S25: 정한솔 | T25: 010-7745-2735 | U25: x | W25: 특약사항 이행, 만기전 퇴실
B26: 20 | C26: 1720 | D26: 26.15 | E26: =D26/3.3058 -> 7.91 | F26: 113500000 | H26: 월세 | I26: 5000000 | J26: 450000 | K26: =I26*3.5%/F26 -> 0.15% | L26: 91287 | M26: =(I26*3.5%-L26)/F26 -> 0.07% | N26: 2025.04.18-2026.04.17 | O26: 46129 | P26: 0 | Q26: =O26-TODAY() -> -31일 | R26: 1720 | S26: 전유빈 | T26: 010-9964-1427 | U26: O
B27: 21 | C27: 1814 | D27: 26.15 | E27: =D27/3.3058 -> 7.91 | F27: 113500000 | H27: 월세 | I27: 5000000 | J27: 420000 | K27: =J27*12/(F27-I27) -> 4.65% | L27: 91287 | N27: 2023.05.31-2026.05.30 | O27: 46172 | P27: 0 | Q27: =O27-TODAY() -> 12일 | R27: 1814 | S27: 이혜민 | T27: 010-3235-1460 | U27: X | W27: 거래신고법 시행 이전 계약, 연장예정
B28: 22 | C28: 1820 | D28: 26.15 | E28: =D28/3.3058 -> 7.91 | F28: 113500000 | H28: 월세 | I28: 5000000 | J28: 450000 | K28: =J28*12/(F28-I28) -> 4.98% | L28: 91287 | M28: =(J28*12-L28)/(F28-I28) -> 4.89% | N28: 2024.12.27-2025.12.26 | O28: 46017 | P28: 0 | Q28: =O28-TODAY() -> -143일 | R28: 1820 | S28: 이경일 | T28: 010-3009-4521 | U28: O
B29: 23 | C29: 1902 | D29: 26.15 | E29: =D29/3.3058 -> 7.91 | F29: 109500000 | H29: 월세 | I29: 5000000 | J29: 420000 | K29: =J29*12/(F29-I29) -> 4.82% | L29: 89727 | N29: 2025.11.25-2026.11.24 | O29: 46350 | P29: 0 | Q29: =O29-TODAY() -> 190일 | R29: 1902 | S29: 박상희 | U29: O
B30: 24 | C30: 1906 | D30: 26.15 | E30: =D30/3.3058 -> 7.91 | F30: 109500000 | H30: 월세 | I30: 5000000 | J30: 420000 | K30: =J30*12/(F30-I30) -> 4.82% | L30: 89727 | N30: 2024.02.23-2026.02.22 | O30: 46075 | P30: 0 | Q30: =O30-TODAY() -> -85일 | R30: 1906 | S30: 박현정 | T30: 010-4536-7420 | U30: O | W30: 연장의사있음/등기로 계약서 작성예정
B31: 25 | C31: 1914 | D31: 26.15 | E31: =D31/3.3058 -> 7.91 | F31: 113500000 | H31: 월세 | I31: 5000000 | J31: 450000 | K31: =J31*12/(F31-I31) -> 4.98% | L31: 91287 | N31: 2025.09.30-2026.09.29 | O31: 46294 | P31: 0 | Q31: =O31-TODAY() -> 134일 | R31: 1914 | S31: 김지혜 | U31: O | W31: 증폭기설치호실(lg)
B32: 26 | C32: 1915 | D32: 26.15 | E32: =D32/3.3058 -> 7.91 | F32: 113500000 | H32: 월세 | I32: 5000000 | J32: 450000 | K32: =J32*12/(F32-I32) -> 4.98% | L32: 91287 | M32: =(J32*12-L32)/(F32-I32) -> 4.89% | N32: 2025.06.16-2026.06.15 | O32: 46188 | P32: 0 | Q32: =O32-TODAY() -> 28일 | R32: 1915 | S32: 정왕 | T32: 010-7164-4752 | U32: O
B33: 27 | C33: 2006 | D33: 26.15 | E33: =D33/3.3058 -> 7.91 | F33: 111000000 | H33: 월세 | I33: 5000000 | J33: 420000 | K33: =J33*12/(F33-I33) -> 4.75% | L33: 89727 | M33: =(J33*12-L33)/(F33-I33) -> 4.67% | N33: 2025.04.18-2026.04.17 | O33: 46129 | P33: 0 | Q33: =O33-TODAY() -> -31일 | R33: 2006 | S33: 이지윤 | T33: 010-3288-2948 | U33: O
B34: 28 | C34: 2013 | D34: 26.15 | E34: =D34/3.3058 -> 7.91 | F34: 111000000 | H34: 월세 | I34: 5000000 | J34: 420000 | K34: =J34*12/(F34-I34) -> 4.75% | L34: 89727 | M34: =(J34*12-L34)/(F34-I34) -> 4.67% | N34: 2023.05.01-2026.04.30 | O34: 46142 | P34: 0 | Q34: =O34-TODAY() -> -18일 | R34: 2013 | S34: 신정현 | T34: 010-9200-1910 | U34: O | W34: 계약연장예정
B35: 29 | C35: 2014 | D35: 26.15 | E35: =D35/3.3058 -> 7.91 | F35: 115000000 | H35: 월세 | I35: 5000000 | J35: 420000 | K35: =J35*12/(F35-I35) -> 4.58% | L35: 91287 | N35: 2024.01.01-2026.12.31 | O35: 46387 | P35: 0 | Q35: =O35-TODAY() -> 227일 | R35: 2014 | S35: 태흥건설 | T35: 054-473-7834 | U35: O | W35: 실거주자: 010-5042-3118/세금계산서 발행 후 매월15~20일 이내 입금
B36: 30 | C36: 2018 | D36: 26.15 | E36: =D36/3.3058 -> 7.91 | F36: 115000000 | H36: 월세 | I36: 5000000 | J36: 450000 | K36: =J36*12/(F36-I36) -> 4.91% | L36: 91287 | M36: =(J36*12-L36)/(F36-I36) -> 4.83% | N36: 2025.06.30-2026.06.30 | O36: 46203 | P36: 0 | Q36: =O36-TODAY() -> 43일 | R36: 2018 | S36: 고승진 | T36: 010-4201-2686 | W36: 임대거래신고 완료, 신고필증 미발급
B37: 31 | C37: 2106 | D37: 26.15 | E37: =D37/3.3058 -> 7.91 | F37: 111000000 | H37: 월세 | I37: 5000000 | J37: 420000 | K37: =J37*12/(F37-I37) -> 4.75% | L37: 89727 | N37: 2024.05.31-2026.05.30 | O37: 46172 | P37: 0 | Q37: =O37-TODAY() -> 12일 | R37: 2106 | S37: 이지원 | T37: 010-5872-0877 | U37: O | W37: 연장예정
B38: 32 | C38: 2111 | D38: 26.15 | E38: =D38/3.3058 -> 7.91 | F38: 111000000 | H38: 월세 | I38: 5000000 | J38: 420000 | K38: =J38*12/(F38-I38) -> 4.75% | L38: 89727 | M38: =(J38*12-L38)/(F38-I38) -> 4.67% | N38: 2023.05.31-2026.05.30 | O38: 46172 | P38: 0 | Q38: =O38-TODAY() -> 12일 | R38: 2111 | S38: 안의형 | T38: 010-6766-4693 | U38: O | W38: 무타공 증폭기설치호실(kt)/연장예정(연장계약서발송완료_5월)
B39: 33 | C39: 2113 | D39: 26.15 | E39: =D39/3.3058 -> 7.91 | F39: 111000000 | H39: 월세 | I39: 5000000 | J39: 420000 | K39: =J39*12/(F39-I39) -> 4.75% | L39: 89727 | N39: 2024.05.27-2026.05.26 | O39: 46168 | P39: 0 | Q39: =O39-TODAY() -> 8일 | R39: 2113 | S39: 서상원 | T39: 010-9422-4717 | U39: O
B40: 34 | C40: 2206 | D40: 26.15 | E40: =D40/3.3058 -> 7.91 | F40: 111000000 | H40: 월세 | I40: 5000000 | J40: 420000 | K40: =J40*12/(F40-I40) -> 4.75% | L40: 89727 | N40: 2024.07.04-2026.07.03 | O40: 46206 | P40: 0 | Q40: =O40-TODAY() -> 46일 | R40: 2206 | S40: 전미정 | T40: 010-2021-8276 | U40: O
B41: 35 | C41: 2213 | D41: 26.15 | E41: =D41/3.3058 -> 7.91 | F41: 111000000 | H41: 월세 | I41: 5000000 | J41: 400000 | K41: =J41*12/(F41-I41) -> 4.53% | L41: 89727 | N41: 2024.04.15-2026.04.14 | O41: 46126 | P41: 0 | Q41: =O41-TODAY() -> -34일 | R41: 2213 | S41: 이연주 | T41: 010-7648-4276 | U41: O
B42: 36 | C42: 2301 | D42: 39.78 | E42: =D42/3.3058 -> 12.03 | F42: 171000000 | H42: 월세 | I42: 10000000 | J42: 600000 | K42: =J42*12/(F42-I42) -> 4.47% | L42: 134272 | N42: 2025.03.28-2026.03.27 | O42: 46108 | P42: 0 | Q42: =O42-TODAY() -> -52일 | R42: 2301 | S42: 이시우 | T42: 010-4447-3524 | U42: O
B43: 37 | C43: 2306 | D43: 26.15 | E43: =D43/3.3058 -> 7.91 | F43: 111000000 | H43: 월세 | I43: 5000000 | J43: 420000 | K43: =J43*12/(F43-I43) -> 4.75% | L43: 89727 | N43: 2023.11.10-2025.11.09 | O43: 45970 | P43: 0 | Q43: =O43-TODAY() -> -190일 | R43: 2306 | S43: 이승철 | T43: 010-2032-9607 | U43: O
B44: 38 | C44: 2313 | D44: 26.15 | E44: =D44/3.3058 -> 7.91 | F44: 111000000 | H44: 월세 | I44: 5000000 | J44: 420000 | K44: =J44*12/(F44-I44) -> 4.75% | L44: 89727 | N44: 2024.12.11-2025-12.10 | O44: 46001 | P44: 0 | Q44: =O44-TODAY() -> -159일 | R44: 2313 | S44: 안하령 | T44: 010-3650-5798 | U44: O | W44: 천장누수/한양에 접수완료/12월 중 현장 실사 후 외벽공사예정
...

Sheet 의정부상가
A1: 의정부 한양수자인파크뷰 상가
A4: 구분 | B4: 순번 | C4: 호수 | D4: 면적(㎡) | E4: 면적(평) | F4: 기존 매입가 (분양가) | G4: 보증금 | H4: 월세 | I4: 수익률 (세전) | J4: 세금 | K4: 수익률 (세후) | L4: 상태 | M4: 임차기간 | N4: 지출 | O4: 미수금 / 미지급 | P4: 연락처 | Q4: 비고
A5: 상가 | B5: 1 | C5: B1 | D5: 751.53 | E5: =D5/3.3058 -> 227.34 | F5: 1500000000 | G5: 50000000 | H5: 5500000 | I5: =H5*12/(F5-J5) -> 4.4% | J5: =1763928+1284709 -> 3,048,637 | K5: =(H5*12-J5)/(F5-G5) -> 4.34% | L5: 임차 | M5: 2022.09.11-2027.10.30 | P5: 010-5141-0245 | Q5: 매년 11월 월세 면제(~27.10.30) 교통유발부담금 임차인부담
B6: 2 | C6: B2 | D6: =E6*3.3058 -> 128.9 | E6: 39 | F6: 300000000 | G6: 10000000 | H6: 850000 | I6: =H6*12/(F6-J6) -> 3.4% | J6: 374720 | K6: =(H6*12-J6)/(F6-G6) -> 3.39% | L6: 공실

Sheet 의정부토지
A1: 의정부동 240-142 토지
A4: 상세현황
A5: 구분 | B5: 순번 | C5: 주소 | D5: 면적(㎡) | E5: 면적(평) | F5: 기존 매입가 (분양가) | G5: 2025 공시지가 | H5: 현상태 | I5: 세금 | J5: 지출 | K5: 미수금 / 미지금
A6: 토지 | B6: 1 | C6: 의정부동 240-142 | D6: 150 | E6: =D6/3.3058 -> 45.37 | F6: =E50 -> 1,437,175,541 | G6: =2842000*D6 -> 426,300,000 | H6: 매각 진행중 | I6: 3197670
E8: =E6*35000000 -> 1588117853
B11: 의정부동 240-142 지출총계
B13: 구분 | C13: 내용 | D13: 지급일 | E13: 금액 | F13: 비고
B14: 토지 | C14: 계약금승계 | D14: 44329 | E14: 130000000 | F14: 2020.06.01 쓰리아이전기
C15: 계약금 | D15: 44329 | E15: 500000000
C16: 잔금 | D16: 44351 | E16: 670000000
C17: 소계 | E17: =SUM(E14:E16) -> 1,300,000,000
B18: 부대비용 | C18: 수입증지 | D18: 44348 | E18: 15000
C19: 등본 | D19: 44348 | E19: 15000
C20: 취득세 | D20: 44348 | E20: 52280000
C21: 지방교육세 | D21: 44348 | E21: 5228000
C22: 농어촌특별세 | D22: 44348 | E22: 2614000
C23: 정부수입인지 | D23: 44348 | E23: 350000
C24: 법무사 보수 | D24: 44348 | E24: 499935
C25: 국민주택채권 | D25: 44348 | E25: 1094565
C26: 등본등제증명 | D26: 44348 | E26: 200000
C27: 중개수수료 | D27: 44351 | E27: 5700000 | F27: 200만원 미지급
C28: 소계 | E28: =SUM(E18:E27) -> 67,996,500
B29: 금융 | C29: 담보대출 | F29: 2021.09.06 10억 대출 2023.03.07 상환 완료
C30: 이자 | D30: 44476 | E30: 3227397
D31: 44508 | E31: 3330107
D32: 44536 | E32: 2912619
D33: 44567 | E33: 3209758
D34: 44599 | E34: 3311906
D35: 44627 | E35: 2917695
D36: 44657 | E36: 3731941
D37: 44691 | E37: 4227752
D38: 44719 | E38: 3476170
D39: 44748 | E39: 3485842
D40: 44781 | E40: 3964975
D41: 44810 | E41: 3482902
D42: 44840 | E42: 4001374
... D48: 44992 | E48: 195415
C49: 소계 | E49: =SUM(E30:E48) -> 69,179,041
B50: 합계 | E50: =E49+E28+E17 -> 1,437,175,541 | G50: =E50/E6 -> 31,673,432.69 | H50: 평당 최소 3200만원 이상으로 매도 필요

Sheet 의정부토지1

Sheet 낙하리
A1: 낙하리 공장
A4: 상세현황
A5: 구분 | B5: 순번 | C5: 주소 | D5: 호수 | E5: 용도 | F5: 면적(㎡) | G5: 면적(평) | H5: 감정가격 | I5: 평당가 | J5: 공시지가 (토지 ㎡당) | K5: 임차인 | L5: 보증금 | M5: 월세 (vat포함) | N5: 미수금 | O5: 수익률(세전) | P5: 세금 | Q5: 수익률 (세후) | R5: 미납내역 | S5: 임차기간 | T5: 매물 현황
A6: 토지 | B6: 1 | C6: 낙하리 301-7 | E6: 공장용지 | F6: 3695 | G6: =F6/3.3058 -> 1,118평 | H6: 2113540000 | I6: =H6/G6 -> 1,890,918 | J6: 326800 | K6: 아래 건물 부분에 기입
B7: 2 | C7: 낙하리 301-9 | E7: 공장용지 | F7: 4225 | G7: =F7/3.3058 -> 1,278평 | H7: 2416700000 | I7: =H7/G7 -> 1,890,918 | J7: 326800
B8: 3 | C8: 낙하리 301-10 | E8: 도로 | F8: 732 | G8: =F8/3.3058 -> 221평 | H8: 138438000 | I8: =H8/G8 -> 625,203 | J8: 104700
B9: 4 | C9: 낙하리 301-11 | E9: 임야 | F9: 527 | G9: =F9/3.3058 -> 159평 | H9: 36890000 | I9: =H9/G9 -> 231,406 | J9: 51800
B10: 5 | C10: 낙하리 301-13 | E10: 임야 | F10: 6295 | G10: =F10/3.3058 -> 1,904평 | H10: 333635000 | I10: =H10/G10 -> 175,207 | J10: 50300
A11: 창고 | B11: 6 | C11: 낙하리 301-7 | D11: 가동 | F11: 198 | G11: =F11/3.3058 -> 60평 | H11: 74646000 | I11: =H11/G11 -> 1,246,287 | N11: 0 | P11: =2370520+5491990 -> 7,862,510 | Q11: =((M11+M19)*12-P11)/((H6+H7+H11+H12+H13+H14+H19+H20)-(L11+L19)) -> -0.15% | R11: 0
B12: 7 | D12: 나동 | F12: 198 | G12: =F12/3.3058 -> 60평 | H12: 74646000 | I12: =H12/G12 -> 1,246,287 | K12: 나일부, 다,라임차 (야스) | L12: 30000000 | M12: 2530000 | S12: 18.03.19~현재 | T12: 야스 부분임차 낙하리 301-7 토지 및 건물중 좌측칸 약 694㎡ 묵시적갱신
B13: 8 | D13: 다동 | F13: 198 | G13: =F13/3.3058 -> 60평 | H13: 74646000 | I13: =H13/G13 -> 1,246,287
B14: 9 | D14: 라동 | F14: 198 | G14: =F14/3.3058 -> 60평 | H14: 74646000 | I14: =H14/G14 -> 1,246,287
B15: 10 | D15: 판넬조지붕단층 | F15: 99.5 | G15: =F15/3.3058 -> 30평 | H15: 35640000 | I15: =H15/G15 -> 1,184,108 | K15: 부분임차 (3I) | L15: 200000000 | M15: 전세 | N15: 0 | S15: 17.06.09~현재 | T15: 3I 부분임차 공장 지붕 약 792㎡ (태양광 인허가 면적)
B16: 11 | D16: 판넬조지붕단층 | F16: 99.5 | G16: =F16/3.3058 -> 30평 | H16: 35640000 | I16: =H16/G16 -> 1,184,108
B17: 13 | D17: 판넬조지붕단층 | F17: 99.5 | G17: =F17/3.3058 -> 30평 | H17: 35640000 | I17: =H17/G17 -> 1,184,108
A18: 301-7 창고 소계 | F18: =SUM(F11:F17) -> 1,091㎡ | G18: =SUM(G11:G17) -> 330평 | H18: =SUM(H11:H17) -> 405,504,000
A19: 공장 | B19: 14 | C19: 낙하리 301-9 | D19: 가동 | F19: 394.02 | G19: =F19/3.3058 -> 119평 | H19: 148546208 | I19: =H19/G19 -> 1,246,292 | N19: 0
B20: 15 | D20: 나동 | F20: 999.9 | G20: =F20/3.3058 -> 302평 | H20: 376963996 | I20: =H20/G20 -> 1,246,292 | R20: 178750000 | T20: 묵시적갱신 지피에스 미납내역178,750,000원
B21: 16 | D21: 판넬조 단층 | G21: =F21/3.3058 -> 평
A22: 301-9 공장 소계 | F22: =F19+F20 -> 1,394㎡ | G22: =G19+G20 -> 422평 | H22: =H19+H20 -> 525,510,204
A23: 토지, 건물 합계 | H23: =SUBTOTAL(109,H6:H10,H18,H22) -> 5,970,217,204 | M23: 미수금 합계 | N23: =SUM(N11:N22) -> 0
F24: =SUM(F6:F10) -> 15,474㎡ | G24: 토지 | H24: =SUM(H6:H10) -> 5,039,203,000

Sheet 낙하리1

Sheet 파주상가
A1: 파주 리버팰리스 단지 상가
A4: 상세현황
A5: 구분 | B5: 순번 | C5: 호수 | D5: 면적(㎡) | E5: 면적(평) | F5: 기존 매입가 (분양가) | G5: 2024년 공시가격 | H5: 현상태 | I5: 보증금 | J5: 월세 | K5: 12월 월세 내역 | L5: 임차기간 | M5: 지출 | N5: 미수금 / 미지급
A6: 상가 | B6: 1 | C6: 1201~1203 | D6: 305 | E6: =D6/3.3058 -> 92.26평 | F6: 462000000 | G6: =84547620+67271535+69202668 -> 221,021,823 | H6: 무상임차
B7: 2 | C7: 1204~1207 | D7: 206 | E7: =D7/3.3058 -> 62.31평 | F7: 314036361 | G7: =39051490+34356960+46211268 -> 119,619,718 | H7: 임차 구하는중
A8: 합계 | D8: =SUM(D6:D7) -> 511.㎡ | E8: =SUM(E6:E7) -> 154.58평 | F8: =SUM(F6:F7) -> 776,036,361

Sheet 보성리
A1: 구분 | F1: 금액 | T1: 지출예정 | U1: 금액예정
A2: 토지 | C2: 토지대 | F2: =F21 -> 43,204,307,767
C3: 취득세 | F3: =F26 -> 993,756,100
C4: 이자 등 | F4: =F60+F63 -> 2,896,303,751
A5: 간접공사비 | F5: =F75 -> 1,220,960,000
A6: 판관비 | F6: =F139 -> 1,123,355,283
A7: 기타관리비 | F7: =F147 -> 55,576,995
A8: 기타 | F8: =F151 -> 202,577,890
A9: 지급금액 합계 | F9: =SUM(F2:F8) -> 49,696,837,786
F10: =F152=F9 -> TRUE | T10: =F5+F6+F7+F8 -> 2,602,470,168
A11: 미지급 합계 | F11: =F159+F164+F177+F183+F169 -> 55,630,298,864 | Z11: 업데이트일 | AA11: =+TODAY() -> 5/18/2026
A14: 연도 | B14: 날짜 | C14: 내용 | D14: 코드 | E14: 거래처명 | F14: 지출금액 | J14: 항목 | M14: 가능 | N14: 확인필요 | S14: 세부항목 | T14: 회수 불가능 | U14: 회수가능 | V14: 확인필요/부분회수 | W14: 회수불가능 | X14: 합계
A15: 2021 | B15: 11-05 | C15: 제주도 사업부지 취득세 대여(추후 토지대금 대체) | D15: 98001 | E15: 기업 216-098709-04-011 | F15: 399699430 | G15: 제주 | I15: 44501 | J15: 토지대 | P15: 불가능 | S15: 토지매입비 | X15: =SUM(U15:W15) -> -
A16: 2022 | B16: 03-08 | C16: 제주도 사업부지 취득세 회수(토지대금 대체) | F16: -399699430 | G16: 제주 | I16: 44621 | J16: 토지대 | P16: 불가능 | X16: =SUM(U16:W16) -> -
A17: 2022 | B17: 03-08 | C17: 서귀포시 대정읍 보성리 2538 계약금 | D17: 98034 | E17: 기업(리파이낸싱)216-098709-04-036 | F17: =8289418970+399699430 -> 8,689,118,400 | G17: 제주 | I17: 44621 | J17: 토지대 | K17: 0 | P17: 불가능 | T17: =F17-U17 -> 8,689,118,400 | U17: =F17-W17 -> - | V17: 2025.05-06월 회수 가능성 있음 | W17: =F17 -> 8,689,118,400 | X17: =SUM(U17:W17) -> 8,689,118,400 | Y17: =F17=X17 -> TRUE
A18: 2022 | B18: 03-08 | C18: 서귀포시 대정읍 보성리 2538 1차 중도금 | D18: 98034 | E18: 기업(리파이낸싱)216-098709-04-036 | F18: 13925997652 | G18: 제주 | I18: 44621 | J18: 토지대 | K18: 0 | L18: 대출 상환 | N18: =F18*3%*(P18-Q18)/365-891932052+13925997652-13926000000 -> 861,596,702 | O18: 납부일부터 정기예금이자율 적용 | P18: =TODAY() -> 5/18/2026 | Q18: 44628 | R18: =P18-Q18 -> 1532 | T18: =F18-U18 -> 327,360,608 | U18: =F18-W18 -> 13,598,637,044 | V18: 2024.10-12월 회수 가능성 있음 | W18: =891932052-564571444 -> 327,360,608 | X18: =SUM(U18:W18) -> 13,925,997,652 | Y18: =F18=X18 -> TRUE
A19: 2022 | B19: 09-07 | C19: 서귀포시 대성읍 보성리 2538 중도2차 | D19: 98039 | E19: 수협 1010-2204-3023 | F19: 13789191715 | G19: 제주 | I19: 44805 | J19: 토지대 | K19: 0 | L19: 대출 상환 | N19: =F19*3%*(P19-Q19)/365-755591715+13789000000-13789191715 -> 773,116,813 | O19: 납부일부터 정기예금이자율 적용 | P19: =TODAY() -> 5/18/2026 | Q19: 44811 | R19: =P19-Q19 -> 1349 | T19: =F19-U19 -> 387,080,066 | U19: =F19-W19 -> 13,402,111,649 | V19: 2024.10-12월 회수 가능성 있음 | W19: =755591715-368511649 -> 387,080,066 | X19: =SUM(U19:W19) -> 13,789,191,715 | Y19: =F19=X19 -> TRUE
A20: 2023 | B20: 03-07 | C20: 제주토지 3차 중도금 일부 | D20: 98001 | E20: 기업 216-098709-04-011 | F20: 6800000000 | G20: 제주 | I20: 44986 | J20: 토지대 | K20: 0 | M20: 6800000000 | N20: =F20*3%*(P20-Q20)/365-6828217827*6.5%*(P20-Q20)/365 -> - 767,469,308 | O20: 납부일부터 정기예금이자율 적용 | P20: =TODAY() -> 5/18/2026 | Q20: 44992 | R20: =P20-Q20 -> 1168 | T20: =F20-U20 -> 709,688,098 | U20: =F20-W20 -> 6,090,311,902 | V20: 2024.10-12월 회수 가능성 있음 | W20: =198205391-83135120+594617827 -> 709,688,098 | X20: =SUM(U20:W20) -> 6,800,000,000 | Y20: =F20=X20 -> TRUE
A21: 합계 토지대 | F21: =SUM(F15:F20) -> 43,204,307,767 | T21: =SUM(T17:T20) -> 10,113,247,172 | U21: =SUM(U17:U20) -> 33,091,060,595
A22: 2022 | B22: 07-04 | C22: 제주 보성리 2538 토지 계약금, 중도1차 취득세 | D22: 98001 | E22: 기업 216-098709-04-011 | F22: 1040409410 | G22: 제주 | I22: 44743 | J22: 토지 취득세 | K22: 0 | M22: 1040409410 | P22: =TODAY() -> 5/18/2026 | Q22: 44746 | R22: =P22-Q22 -> 1414 | S22: 취득세 | T22: =F22-U22 -> - | U22: =F22 -> 1,040,409,410 | X22: =SUM(U22:W22) -> 1,040,409,410 | Y22: =F22=X22 -> TRUE
A23: 2022 | B23: 11-07 | C23: 제주 보성리 2538 토지 중도2차 취득세 | D23: 98001 | E23: 기업 216-098709-04-011 | F23: 634302800 | G23: 제주 | I23: 44866 | J23: 토지 취득세 | K23: 0 | M23: 634302800 | P23: =TODAY() -> 5/18/2026 | Q23: 44872 | R23: =P23-Q23 -> 1288 | T23: =F23-U23 -> - | U23: =F23 -> 634,302,800 | X23: =SUM(U23:W23) -> 634,302,800 | Y23: =F23=X23 -> TRUE
A24: 2023 | B24: 05-08 | C24: 제주토지3차 일부 취득세 68억*4.6% | D24: 98001 | E24: 기업 216-098709-04-011 | F24: 312800000 | G24: 제주 | I24: 45047 | J24: 토지 취득세 | K24: 0 | M24: 312800000 | P24: =TODAY() -> 5/18/2026 | Q24: 45054 | R24: =P24-Q24 -> 1106 | T24: =F24-U24 -> - | U24: =F24 -> 312,800,000 | X24: =SUM(U24:W24) -> 312,800,000 | Y24: =F24=X24 -> TRUE
A25: 2023 | B25: 07-25 | C25: 제주 토지 취득세 환급(50%) | D25: 98039 | E25: 수협 1010-2204-3023 | F25: -993756110 | G25: 제주 | I25: 45084 | J25: 토지 취득세 | K25: 0 | M25: -993756110 | T25: =F25-U25 -> - | U25: =F25 -> - 993,756,110 | X25: =SUM(U25:W25) -> - 993,756,110 | Y25: =F25=X25 -> TRUE
A26: 합계 취득세 | F26: =SUM(F22:F25) -> 993,756,100 | T26: =SUM(T22:T25) -> - | U26: =SUM(U22:U25) -> 993,756,100
A27: 2022 | B27: 08-12 | C27: 제주토지이자 139.26억*4.58%*31/365 | D27: 98039 | E27: 수협 1010-2204-3023 | F27: 54170232 | G27: 제주 | I27: 44774 | J27: 토지대 이자 | P27: 불가능 | S27: 토지담보대출이자 | T27: =F27-U27 -> 54,170,232 | W27: 54170232 | X27: =SUM(U27:W27) -> 54,170,232 | Y27: =F27=X27 -> TRUE
A28: 2022 | B28: 09-13 | C28: 제주토지이자 277.15억*4.58%*31(3)/365 | D28: 98039 | E28: 수협 1010-2204-3023 | F28: 62821412 | G28: 제주 | I28: 44805 | J28: 토지대 이자 | P28: 불가능 | T28: =F28-U28 -> 62,821,412 | W28: 62821412 | X28: =SUM(U28:W28) -> 62,821,412 | Y28: =F28=X28 -> TRUE
A29: 2022 | B29: 10-12 | C29: 제주토지이자 277.15억*4.58%*30/365 | D29: 98039 | E29: 수협 1010-2204-3023 | F29: 104329889 | G29: 제주 | I29: 44835 | J29: 토지대 이자 | P29: 불가능 | T29: =F29-U29 -> 104,329,889 | W29: 104329889 | X29: =SUM(U29:W29) -> 104,329,889 | Y29: =F29=X29 -> TRUE
A30: 2022 | B30: 11-14 | C30: 제주토지이자 277.15억*5.05%*31/365 | D30: 98039 | E30: 수협 1010-2204-3023 | F30: 118870773 | G30: 제주 | I30: 44866 | J30: 토지대 이자 | P30: 불가능 | T30: =F30-U30 -> 118,870,773 | W30: 118870773 | X30: =SUM(U30:W30) -> 118,870,773 | Y30: =F30=X30 -> TRUE
A31: 2022 | B31: 12-12 | C31: 제주토지이자 277.15억*5.05%*31/365 | D31: 98039 | E31: 수협 1010-2204-3023 | F31: 115036232 | G31: 제주 | I31: 44896 | J31: 토지대 이자 | P31: 불가능 | T31: =F31-U31 -> 115,036,232 | W31: 115036232 | X31: =SUM(U31:W31) -> 115,036,232 | Y31: =F31=X31 -> TRUE
A32: 2023 | B32: 01-12 | C32: 제주토지 이자 277.15억*5.05%*31/365 | D32: 98039 | E32: 수협 1010-2204-3023 | F32: 118870773 | G32: 제주 | I32: 44927 | J32: 토지대 이자 | P32: 불가능 | T32: =F32-U32 -> 118,870,773 | W32: 118870773 | X32: =SUM(U32:W32) -> 118,870,773 | Y32: =F32=X32 -> TRUE
A33: 2023 | B33: 02-13 | C33: 제주토지 이자 277.15억*5.86%*31/365 | D33: 98039 | E33: 수협 1010-2204-3023 | F33: 137937175 | G33: 제주 | I33: 44958 | J33: 토지대 이자 | P33: 불가능 | T33: =F33-U33 -> 137,937,175 | W33: 137937175 | X33: =SUM(U33:W33) -> 137,937,175 | Y33: =F33=X33 -> TRUE
A34: 2023 | B34: 03-13 | C34: 제주토지 이자 277.15억*5.86%*28/365 | D34: 98039 | E34: 수협 1010-2204-3023 | F34: 124588416 | G34: 제주 | I34: 44986 | J34: 토지대 이자 | P34: 불가능 | T34: =F34-U34 -> 124,588,416 | W34: 124588416 | X34: =SUM(U34:W34) -> 124,588,416 | Y34: =F34=X34 -> TRUE
A35: 2023 | B35: 04-12 | C35: 제주토지 이자 277.15억*5.86%*31/365 | D35: 98039 | E35: 수협 1010-2204-3023 | F35: 137937175 | G35: 제주 | I35: 45017 | J35: 토지대 이자 | P35: 불가능 | T35: =F35-U35 -> 137,937,175 | W35: 137937175 | X35: =SUM(U35:W35) -> 137,937,175 | Y35: =F35=X35 -> TRUE
A36: 2023 | B36: 05-12 | C36: 제주토지 이자 277.15억*6.64%*30/365 | D36: 98039 | E36: 수협 1010-2204-3023 | F36: 151255560 | G36: 제주 | I36: 45047 | J36: 토지대 이자 | P36: 불가능 | T36: =F36-U36 -> 151,255,560 | W36: 151255560 | X36: =SUM(U36:W36) -> 151,255,560 | Y36: =F36=X36 -> TRUE
A37: 2023 | B37: 06-12 | C37: 제주토지 이자 277.15억*6.64%*31/365 | D37: 98039 | E37: 수협 1010-2204-3023 | F37: 156297413 | G37: 제주 | I37: 45078 | J37: 토지대 이자 | P37: 불가능 | T37: =F37-U37 -> 156,297,413 | W37: 156297413 | X37: =SUM(U37:W37) -> 156,297,413 | Y37: =F37=X37 -> TRUE
A38: 2023 | B38: 07-12 | C38: 제주토지 이자 277.15억*6.64%*30/365 | D38: 98039 | E38: 수협 1010-2204-3023 | F38: 151255560 | G38: 제주 | I38: 45084 | J38: 토지대 이자 | P38: 불가능 | T38: =F38-U38 -> 151,255,560 | W38: 151255560 | X38: =SUM(U38:W38) -> 151,255,560 | Y38: =F38=X38 -> TRUE
A39: 2023 | B39: 08-12 | C39: 제주토지 이자 277.15억*0.5% 선취수수료 | D39: 98039 | E39: 수협 1010-2204-3023 | F39: 138575000 | G39: 제주 | I39: 45084 | J39: 토지대 이자 | P39: 불가능 | T39: =F39-U39 -> 138,575,000 | W39: 138575000 | X39: =SUM(U39:W39) -> 138,575,000 | Y39: =F39=X39 -> TRUE
... A41: 2023 | B41: 09-12 | C41: 제주토지 이자 277.15억*5.40%*31/365 | D41: 98039 | E41: 수협 1010-2204-3023 | F41: 127109341 | G41: 제주 | I41: 45084 | J41: 토지대 이자 | P41: 불가능 | T41: =F41-U41 -> 127,109,341 | W41: 127109341 | X41: =SUM(U41:W41) -> 127,109,341 | Y41: =F41=X41 -> TRUE
A42: 2023 | B42: 10-12 | C42: 제주토지 이자 277.15억*5.40%*30/365 | F42: 123009040 | T42: =F42-U42 -> 123,009,040
A43: 2023 | B43: 11-13 | C43: 제주토지 이자 277.15억*5.40%*31/365 | F43: 128521667 | T43: =F43-U43 -> 128,521,667
...

Sheet 향남 에듀스퀘어
A1: 향남역 에듀스퀘어
AC2: ** 계약시 할인 금액 확인 가능 | AE2: ** 계약시 할인 금액 확인 가능
A4: 상세현황 | AK4: 선임대 | AZ4: 수수료(VAT포함)
A5: 순번 | B5: 분양여부 | C5: 용도 | D5: 호실 | E5: 원가 | G5: 전용면적(평) | H5: 분양면적(평) | I5: 기존분양가(VAT제외) | J5: 기존분양가(유성) | N5: 기존분양가(VAT포함) | O5: 할인분양가(VAT제외) | P5: 할인분양가(선인) | T5: 최종할인분양가(VAT포함) | U5: 할인금액 | V5: 할인율 | W5: 이름 | X5: 전화번호 | Y5: 계약일자 | Z5: 계약금 | AC5: 중도금 | AE5: 잔금 | AG5: 잔액 | AH5: 입금합계 | AI5: 인테리어 시작일 | AJ5: 비고 | AK5: 임대 | AZ5: 총 수수료 | BA5: 지출예상수수료
E6: 건물비율 | F6: 토지비율 | J6: 건물 | K6: 토지 | L6: 부가세 | M6: 합계 | P6: 건물 | Q6: 토지 | R6: 부가세 | S6: 합계 | Z6: 입금일 | AA6: 입금액 | AB6: 비율 | AC6: 입금예상일 | AD6: 입금액 | AE6: 입금예상일 | AF6: 입금액 | AK6: 호실 | AL6: 선임대여부 | AM6: 이름 | AN6: 연락처 | AO6: 업종 | AP6: 계약기간 | AQ6: 계약만기일 | AR6: 잔여일 | AS6: 보증금 | AT6: 월세(vat미포함) | AU6: 할인전 수익률 | AV6: 할인후 수익률 | AW6: 임대료 납부일 | AX6: 미수금 | AY6: 비고 | BA6: 지출예상 분양수수료 | BB6: 지출예상 선임대수수료
A7: 1 | C7: 1종근린생활시설 | D7: 103 | E7: 0.85385265 | F7: 0.14614735 | G7: 8.74225 | H7: 13.2858 | I7: 411500000 | J7: =ROUND(I7*E7,-3) -> 351,360,000 | K7: =ROUND(I7*F7,-3) -> 60,140,000 | L7: =ROUND(J7*10%,-3) -> 35,136,000 | M7: =SUM(J7:L7) -> 446,636,000 | N7: =(M7) -> 446,636,000 | P7: =ROUND(O7*E7,-3) -> - | Q7: =ROUND(O7*F7,-3) -> - | R7: =ROUND(P7*0.1,-3) -> - | S7: =SUM(P7:R7) -> - | T7: =N7*(1-0.22) -> 348,376,080 | U7: =N7-T7 -> 98,259,920 | V7: =U7/N7 -> 22% | AB7: =AA7/T7 -> 0% | AG7: =T7-AH7 -> 348,376,080 | AH7: =AA7+AF7 -> - | AI7: 45505 | AK7: 103 | AL7: 선임대 | AM7: 고승권 | AO7: GS마트 | AP7: 2024.08.01-2029.07.31 | AQ7: 47330 | AR7: =(AQ7-TODAY()) -> 1170일 | AS7: 30000000 | AT7: 1850000 | AU7: =AT7*12/(N7-AS7) -> 5.33% | AV7: =AT7*12/(T7-AS7) -> 6.97% | AW7: 매월 15일(후불) | AX7: 0 | AZ7: =(T7-(N7*65%))*1.1 -> 63,868,948 | BA7: =AZ7-BB7 -> 52,043,948 | BB7: =(AS7+(AT7*100))*5%*1.1 -> 11,825,000
A8: =A7+1 -> 2 | D8: 105 | E8: 0.85383349 | F8: 0.14616651 | G8: 10.729675 | H8: 16.307775 | I8: 449000000 | J8: =ROUND(I8*E8,-3) -> 383,371,000 | K8: =ROUND(I8*F8,-3) -> 65,629,000 | L8: =ROUND(J8*10%,-3) -> 38,337,000 | M8: =SUM(J8:L8) -> 487,337,000 | N8: =(M8) -> 487,337,000 | P8: =ROUND(O8*E8,-3) -> - | Q8: =ROUND(O8*F8,-3) -> - | R8: =ROUND(P8*0.1,-3) -> - | S8: =SUM(P8:R8) -> - | T8: =N8*(1-0.22) -> 380,122,860 | U8: =N8-T8 -> 107,214,140 | V8: =U8/N8 -> 22% | AB8: =AA8/T8 -> 0% | AG8: =T8-AH8 -> 380,122,860 | AH8: =AA8+AF8 -> - | AI8: 45505 | AK8: 105 | AL8: 선임대 | AM8: 고승권 | AO8: GS마트 | AP8: 2024.08.01-2029.07.31 | AQ8: 47330 | AR8: =(AQ8-TODAY()) -> 1170일 | AS8: 30000000 | AT8: 1600000 | AU8: =AT8*12/(N8-AS8) -> 4.20% | AV8: =AT8*12/(T8-AS8) -> 5.48% | AW8: 매월 15일(후불) | AX8: 0 | AZ8: =(T8-(N8*65%))*1.1 -> 69,689,191 | BA8: =AZ8-BB8 -> 59,239,191 | BB8: =(AS8+(AT8*100))*5%*1.1 -> 10,450,000
A9: =A8+1 -> 3 | D9: 108 | E9: 0.85383349 | F9: 0.14616651 | G9: 10.729675 | H9: 16.307775 | I9: 449000000 | J9: =ROUND(I9*E9,-3) -> 383,371,000 | K9: =ROUND(I9*F9,-3) -> 65,629,000 | L9: =ROUND(J9*10%,-3) -> 38,337,000 | M9: =SUM(J9:L9) -> 487,337,000 | N9: =(M9) -> 487,337,000 | P9: =ROUND(O9*E9,-3) -> - | Q9: =ROUND(O9*F9,-3) -> - | R9: =ROUND(P9*0.1,-3) -> - | S9: =SUM(P9:R9) -> - | T9: =N9*(1-0.22) -> 380,122,860 | U9: =N9-T9 -> 107,214,140 | V9: =U9/N9 -> 22% | AB9: =AA9/T9 -> 0% | AG9: =T9-AH9 -> 380,122,860 | AH9: =AA9+AF9 -> - | AK9: 108 | AU9: =AT9*12/(N9-AS9) -> 0.00% | AV9: =AT9*12/(T9-AS9) -> 0.00% | AZ9: =(T9-(N9*65%))*1.1 -> 69,689,191 | BA9: =AZ9-BB9 -> 69,689,191 | BB9: =(AS9+(AT9*100))*5%*1.1 -> -
A10: =A9+1 -> 4 | D10: 109 | E10: 0.85383349 | F10: 0.14616651 | G10: 10.729675 | H10: 16.307775 | I10: 449000000 | J10: =ROUND(I10*E10,-3) -> 383,371,000 | K10: =ROUND(I10*F10,-3) -> 65,629,000 | L10: =ROUND(J10*10%,-3) -> 38,337,000 | M10: =SUM(J10:L10) -> 487,337,000 | N10: =(M10) -> 487,337,000 | P10: =ROUND(O10*E10,-3) -> - | Q10: =ROUND(O10*F10,-3) -> - | R10: =ROUND(P10*0.1,-3) -> - | S10: =SUM(P10:R10) -> - | T10: =N10*(1-0.22) -> 380,122,860 | U10: =N10-T10 -> 107,214,140 | V10: =U10/N10 -> 22% | AB10: =AA10/T10 -> 0% | AG10: =T10-AH10 -> 380,122,860 | AH10: =AA10+AF10 -> - | AK10: 109 | AL10: 선임대 | AO10: 중개사무소 | AQ10: 46599 | AR10: =(AQ10-TODAY()) -> 439일 | AS10: 30000000 | AT10: 1300000 | AU10: =AT10*12/(N10-AS10) -> 3.41% | AV10: =AT10*12/(T10-AS10) -> 4.46% | AW10: 매월 2일(선불) | AY10: 렌트프리3개월(10/31까지) | AZ10: =(T10-(N10*65%))*1.1 -> 69,689,191 | BA10: =AZ10-BB10 -> 60,889,191 | BB10: =(AS10+(AT10*100))*5%*1.1 -> 8,800,000
A11: =A10+1 -> 5 | D11: 110 | E11: 0.85383349 | F11: 0.14616651 | G11: 10.729675 | H11: 16.307775 | I11: 449000000 | J11: =ROUND(I11*E11,-3) -> 383,371,000 | K11: =ROUND(I11*F11,-3) -> 65,629,000 | L11: =ROUND(J11*10%,-3) -> 38,337,000 | M11: =SUM(J11:L11) -> 487,337,000 | N11: =(M11) -> 487,337,000 | P11: =ROUND(O11*E11,-3) -> - | Q11: =ROUND(O11*F11,-3) -> - | R11: =ROUND(P11*0.1,-3) -> - | S11: =SUM(P11:R11) -> - | T11: =N11*(1-0.22) -> 380,122,860 | U11: =N11-T11 -> 107,214,140 | V11: =U11/N11 -> 22% | AB11: =AA11/T11 -> 0% | AG11: =T11-AH11 -> 380,122,860 | AH11: =AA11+AF11 -> - | AK11: 110 | AU11: =AT11*12/(N11-AS11) -> 0.00% | AV11: =AT11*12/(T11-AS11) -> 0.00% | AZ11: =(T11-(N11*65%))*1.1 -> 69,689,191 | BA11: =AZ11-BB11 -> 69,689,191 | BB11: =(AS11+(AT11*100))*5%*1.1 -> -
A12: =A11+1 -> 6 | D12: 111 | E12: 0.85383349 | F12: 0.14616651 | G12: 10.729675 | H12: 16.307775 | I12: 457100000 | J12: =ROUND(I12*E12,-3) -> 390,287,000 | K12: =ROUND(I12*F12,-3) -> 66,813,000 | L12: =ROUND(J12*10%,-3) -> 39,029,000 | M12: =SUM(J12:L12) -> 496,129,000 | N12: =(M12) -> 496,129,000 | P12: =ROUND(O12*E12,-3) -> - | Q12: =ROUND(O12*F12,-3) -> - | R12: =ROUND(P12*0.1,-3) -> - | S12: =SUM(P12:R12) -> - | T12: =N12*(1-0.22) -> 386,980,620 | U12: =N12-T12 -> 109,148,380 | V12: =U12/N12 -> 22% | AB12: =AA12/T12 -> 0% | AG12: =T12-AH12 -> 386,980,620 | AH12: =AA12+AF12 -> - | AK12: 111 | AU12: =AT12*12/(N12-AS12) -> 0.00% | AV12: =AT12*12/(T12-AS12) -> 0.00% | AZ12: =(T12-(N12*65%))*1.1 -> 70,946,447 | BA12: =AZ12-BB12 -> 70,946,447 | BB12: =(AS12+(AT12*100))*5%*1.1 -> -
D13: 소계 | G13: 151.25 | H13: 229.88487 | I13: 6487600000 | N13: =SUM(N7:N12) -> 2,892,113,000 | O13: =SUM(O7:O12) -> 0 | T13: =SUM(T7:T12) -> 2,255,848,140 | U13: =SUM(U7:U12) -> 636,264,860 | AA13: =SUM(AA7:AA12) -> 0 | AD13: =SUM(AD7:AD12) -> 0 | AF13: =SUM(AF7:AF12) -> 0 | AG13: =SUM(AG7:AG12) -> 2,255,848,140 | AH13: =SUM(AH7:AH12) -> - | AS13: =SUM(AS7:AS12) -> 90,000,000 | AT13: =SUM(AT7:AT12) -> 4,750,000 | AZ13: =SUM(AZ7:AZ12) -> 413,572,159
A14: 7 | D14: 203 | E14: 0.87051055 | F14: 0.12948945 | G14: 21.534975 | H14: 37.66125 | I14: 393200000 | J14: =ROUND(I14*E14,-3) -> 342,285,000 | K14: =ROUND(I14*F14,-3) -> 50,915,000 | L14: =ROUND(J14*10%,-3) -> 34,229,000 | M14: =SUM(J14:L14) -> 427,429,000 | N14: =(M14) -> 427,429,000 | P14: =ROUND(O14*E14,-3) -> - | Q14: =ROUND(O14*F14,-3) -> - | R14: =ROUND(P14*0.1,-3) -> - | S14: =SUM(P14:R14) -> - | T14: =N14*(1-0.22) -> 333,394,620 | U14: =N14-T14 -> 94,034,380 | V14: =U14/N14 -> 22% | AB14: =AA14/T14 -> 0% | AG14: =T14-AH14 -> 333,394,620 | AH14: =AA14+AF14 -> - | AK14: 203 | AU14: =AT14*12/(N14-AS14) -> 0.00% | AV14: =AT14*12/(T14-AS14) -> 0.00% | AZ14: =(T14-(N14*65%))*1.1 -> 61,122,347 | BA14: =AZ14-BB14 -> 61,122,347 | BB14: =(AS14+(AT14*100))*5%*1.1 -> -
A15: =A14+1 -> 8 | D15: 204 | E15: 0.87048771 | F15: 0.12951229 | G15: 21.97965 | H15: 38.438675 | I15: 411300000 | J15: =ROUND(I15*E15,-3) -> 358,032,000 | K15: =ROUND(I15*F15,-3) -> 53,268,000 | L15: =ROUND(J15*10%,-3) -> 35,803,000 | M15: =SUM(J15:L15) -> 447,103,000 | N15: =(M15) -> 447,103,000 | P15: =ROUND(O15*E15,-3) -> - | Q15: =ROUND(O15*F15,-3) -> - | R15: =ROUND(P15*0.1,-3) -> - | S15: =SUM(P15:R15) -> - | T15: =N15*(1-0.22) -> 348,740,340 | U15: =N15-T15 -> 98,362,660 | V15: =U15/N15 -> 22% | AB15: =AA15/T15 -> 0% | AG15: =T15-AH15 -> 348,740,340 | AH15: =AA15+AF15 -> - | AK15: 204 | AU15: =AT15*12/(N15-AS15) -> 0.00% | AV15: =AT15*12/(T15-AS15) -> 0.00% | AZ15: =(T15-(N15*65%))*1.1 -> 63,935,729 | BA15: =AZ15-BB15 -> 63,935,729 | BB15: =(AS15+(AT15*100))*5%*1.1 -> -
A16: =A15+1 -> 9 | D16: 205 | E16: 0.87048771 | F16: 0.12951229 | G16: 21.97965 | H16: 38.438675 | I16: 411300000 | J16: =ROUND(I16*E16,-3) -> 358,032,000 | K16: =ROUND(I16*F16,-3) -> 53,268,000 | L16: =ROUND(J16*10%,-3) -> 35,803,000 | M16: =SUM(J16:L16) -> 447,103,000 | N16: =(M16) -> 447,103,000 | P16: =ROUND(O16*E16,-3) -> - | Q16: =ROUND(O16*F16,-3) -> - | R16: =ROUND(P16*0.1,-3) -> - | S16: =SUM(P16:R16) -> - | T16: =N16*(1-0.22) -> 348,740,340 | U16: =N16-T16 -> 98,362,660 | V16: =U16/N16 -> 22% | AB16: =AA16/T16 -> 0% | AG16: =T16-AH16 -> 348,740,340 | AH16: =AA16+AF16 -> - | AK16: 205 | AU16: =AT16*12/(N16-AS16) -> 0.00% | AV16: =AT16*12/(T16-AS16) -> 0.00% | AZ16: =(T16-(N16*65%))*1.1 -> 63,935,729 | BA16: =AZ16-BB16 -> 63,935,729 | BB16: =(AS16+(AT16*100))*5%*1.1 -> -
A17: =A16+1 -> 10 | D17: 206 | E17: 0.87048771 | F17: 0.12951229 | G17: 21.97965 | H17: 38.438675 | I17: 411300000 | J17: =ROUND(I17*E17,-3) -> 358,032,000 | K17: =ROUND(I17*F17,-3) -> 53,268,000 | L17: =ROUND(J17*10%,-3) -> 35,803,000 | M17: =SUM(J17:L17) -> 447,103,000 | N17: =(M17) -> 447,103,000 | P17: =ROUND(O17*E17,-3) -> - | Q17: =ROUND(O17*F17,-3) -> - | R17: =ROUND(P17*0.1,-3) -> - | S17: =SUM(P17:R17) -> - | T17: =N17*(1-0.22) -> 348,740,340 | U17: =N17-T17 -> 98,362,660 | V17: =U17/N17 -> 22% | AB17: =AA17/T17 -> 0% | AG17: =T17-AH17 -> 348,740,340 | AH17: =AA17+AF17 -> - | AK17: 206 | AU17: =AT17*12/(N17-AS17) -> 0.00% | AV17: =AT17*12/(T17-AS17) -> 0.00% | AZ17: =(T17-(N17*65%))*1.1 -> 63,935,729 | BA17: =AZ17-BB17 -> 63,935,729 | BB17: =(AS17+(AT17*100))*5%*1.1 -> -
A18: =A17+1 -> 11 | D18: 207 | E18: 0.87048434 | F18: 0.12951566 | G18: 23.3772 | H18: 40.87985 | I18: 459200000 | J18: =ROUND(I18*E18,-3) -> 399,726,000 | K18: =ROUND(I18*F18,-3) -> 59,474,000 | L18: =ROUND(J18*10%,-3) -> 39,973,000 | M18: =SUM(J18:L18) -> 499,173,000 | N18: =(M18) -> 499,173,000 | P18: =ROUND(O18*E18,-3) -> - | Q18: =ROUND(O18*F18,-3) -> - | R18: =ROUND(P18*0.1,-3) -> - | S18: =SUM(P18:R18) -> - | T18: =N18*(1-0.22) -> 389,354,940 | U18: =N18-T18 -> 109,818,060 | V18: =U18/N18 -> 22% | AB18: =AA18/T18 -> 0% | AG18: =T18-AH18 -> 389,354,940 | AH18: =AA18+AF18 -> - | AK18: 207 | AU18: =AT18*12/(N18-AS18) -> 0.00% | AV18: =AT18*12/(T18-AS18) -> 0.00% | AZ18: =(T18-(N18*65%))*1.1 -> 71,381,739 | BA18: =AZ18-BB18 -> 71,381,739 | BB18: =(AS18+(AT18*100))*5%*1.1 -> -
A19: =A18+1 -> 12 | D19: 208 | E19: 0.87046411 | F19: 0.12953589 | G19: 11.04125 | H19: 19.302525 | I19: 201000000 | J19: =ROUND(I19*E19,-3) -> 174,963,000 | K19: =ROUND(I19*F19,-3) -> 26,037,000 | L19: =ROUND(J19*10%,-3) -> 17,496,000 | M19: =SUM(J19:L19) -> 218,496,000 | N19: =(M19) -> 218,496,000 | P19: =ROUND(O19*E19,-3) -> - | Q19: =ROUND(O19*F19,-3) -> - | R19: =ROUND(P19*0.1,-3) -> - | S19: =SUM(P19:R19) -> - | T19: =N19*(1-0.22) -> 170,426,880 | U19: =N19-T19 -> 48,069,120 | V19: =U19/N19 -> 22% | AB19: =AA19/T19 -> 0% | AG19: =T19-AH19 -> 170,426,880 | AH19: =AA19+AF19 -> - | AK19: 208 | AL19: 선임대 | AM19: 최수연 | AO19: 교습소 | AP19: 2024.08.01-2026.07.31 | AQ19: 46234 | AR19: =(AQ19-TODAY()) -> 74일 | AS19: 15000000 | AT19: 850000 | AU19: =AT19*12/(N19-AS19) -> 5.01% | AV19: =AT19*12/(T19-AS19) -> 6.56% | AW19: 매월 2일(선불) | AX19: 0 | AZ19: =(T19-(N19*65%))*1.1 -> 31,244,928 | BA19: =AZ19-BB19 -> 25,744,928 | BB19: =(AS19+(AT19*100))*5%*1.1 -> 5,500,000
D20: 소계 | G20: 164.47832 | H20: 287.63212 | I20: 3117900000 | N20: =SUM(N14:N19) -> 2,486,407,000 | O20: =SUM(O14:O19) -> 0 | S20: =SUM(S14:S19) -> - | T20: =SUM(T14:T19) -> 1,939,397,460 | U20: =SUM(U14:U19) -> 547,009,540 | AA20: =SUM(AA14:AA19) -> 0 | AD20: =SUM(AD14:AD19) -> 0 | AF20: =SUM(AF14:AF19) -> 0 | AG20: =SUM(AG14:AG19) -> 1,939,397,460 | AH20: =SUM(AH14:AH19) -> - | AS20: =SUM(AS14:AS19) -> 15,000,000 | AT20: =SUM(AT14:AT19) -> 850,000 | AZ20: =SUM(AZ14:AZ19) -> 355,556,201
A21: 13 | C21: 2종근린생활시설 | D21: 301 | E21: 0.87049171 | F21: 0.12950829 | G21: 21.371625 | H21: 37.373875 | I21: 390500000 | J21: =ROUND(I21*E21,-3) -> 339,927,000 | K21: =ROUND(I21*F21,-3) -> 50,573,000 | L21: =ROUND(J21*10%,-3) -> 33,993,000 | M21: =SUM(J21:L21) -> 424,493,000 | N21: =(M21) -> 424,493,000 | P21: =ROUND(O21*E21,-3) -> - | Q21: =ROUND(O21*F21,-3) -> - | R21: =ROUND(P21*0.1,-3) -> - | S21: =SUM(P21:R21) -> - | T21: =N21*(1-0.22) -> 331,104,540 | U21: =N21-T21 -> 93,388,460 | V21: =U21/N21 -> 22% | AB21: =AA21/T21 -> 0% | AG21: =T21-AH21 -> 331,104,540 | AH21: =AA21+AF21 -> - | AK21: 301 | AU21: =AT21*12/(N21-AS21) -> 0.00% | AV21: =AT21*12/(T21-AS21) -> 0.00% | AZ21: =(T21-(N21*65%))*1.1 -> 60,702,499 | BA21: =AZ21-BB21 -> 60,702,499 | BB21: =(AS21+(AT21*100))*5%*1.1 -> -
A22: 14 | D22: 302 | E22: 0.87047989 | F22: 0.12952011 | G22: 21.214325 | H22: 37.0986 | I22: 391500000 | J22: =ROUND(I22*E22,-3) -> 340,793,000 | K22: =ROUND(I22*F22,-3) -> 50,707,000 | L22: =ROUND(J22*10%,-3) -> 34,079,000 | M22: =SUM(J22:L22) -> 425,579,000 | N22: =(M22) -> 425,579,000 | P22: =ROUND(O22*E22,-3) -> - | Q22: =ROUND(O22*F22,-3) -> - | R22: =ROUND(P22*0.1,-3) -> - | S22: =SUM(P22:R22) -> - | T22: =N22*(1-0.22) -> 331,951,620 | U22: =N22-T22 -> 93,627,380 | V22: =U22/N22 -> 22% | AB22: =AA22/T22 -> 0% | AG22: =T22-AH22 -> 331,951,620 | AH22: =AA22+AF22 -> - | AK22: 302 | AU22: =AT22*12/(N22-AS22) -> 0.00% | AV22: =AT22*12/(T22-AS22) -> 0.00% | AZ22: =(T22-(N22*65%))*1.1 -> 60,857,797 | BA22: =AZ22-BB22 -> 60,857,797 | BB22: =(AS22+(AT22*100))*5%*1.1 -> -
A23: 15 | D23: 303 | E23: 0.87051055 | F23: 0.12948945 | G23: 21.534975 | H23: 37.66125 | I23: 375700000 | J23: =ROUND(I23*E23,-3) -> 327,051,000 | K23: =ROUND(I23*F23,-3) -> 48,649,000 | L23: =ROUND(J23*10%,-3) -> 32,705,000 | M23: =SUM(J23:L23) -> 408,405,000 | N23: =(M23) -> 408,405,000 | P23: =ROUND(O23*E23,-3) -> - | Q23: =ROUND(O23*F23,-3) -> - | R23: =ROUND(P23*0.1,-3) -> - | S23: =SUM(P23:R23) -> - | T23: =N23*(1-0.22) -> 318,555,900 | U23: =N23-T23 -> 89,849,100 | V23: =U23/N23 -> 22% | AB23: =AA23/T23 -> 0% | AG23: =T23-AH23 -> 318,555,900 | AH23: =AA23+AF23 -> - | AK23: 303 | AU23: =AT23*12/(N23-AS23) -> 0.00% | AV23: =AT23*12/(T23-AS23) -> 0.00% | AZ23: =(T23-(N23*65%))*1.1 -> 58,401,915 | BA23: =AZ23-BB23 -> 58,401,915 | BB23: =(AS23+(AT23*100))*5%*1.1 -> -
A24: 16 | D24: 304 | E24: 0.87048771 | F24: 0.12951229 | G24: 100.4 | H24: 175.5 | I24: 1762000000 | J24: 1533794000 | K24: 228206000 | L24: =ROUND(J24*10%,-3) -> 153,379,000 | M24: =SUM(J24:L28) -> 1,915,379,000 | N24: =M24 -> 1,915,379,000 | P24: =ROUND(O24*E24,-3) -> - | Q24: =ROUND(O24*F24,-3) -> - | R24: =ROUND(P24*0.1,-3) -> - | S24: =SUM(P24:R24) -> - | T24: =N24*(1-0.22) -> 1,493,995,620 | U24: =N24-T24 -> 421,383,380 | V24: =U24/N24 -> 22% | AB24: =AA24/T24 -> 0% | AG24: =T24-AH24 -> 1,493,995,620 | AH24: =AA24+AF24 -> - | AI24: 45474 | AK24: 304 | AL24: 잉글루(영어학원), 코딩 | BA24: =AZ24-BB24 -> -
A25: 17 | D25: 305 | E25: 0.87048771 | F25: 0.12951229 | P25: =ROUND(O25*E25,-3) -> - | Q25: =ROUND(O25*F25,-3) -> - | R25: =ROUND(P25*0.1,-3) -> - | S25: =SUM(P25:R25) -> - | AK25: 305
A26: 18 | D26: 306 | E26: 0.87048771 | F26: 0.12951229 | P26: =ROUND(O26*E26,-3) -> - | Q26: =ROUND(O26*F26,-3) -> - | R26: =ROUND(P26*0.1,-3) -> - | S26: =SUM(P26:R26) -> - | AK26: 306
A27: 19 | D27: 307 | E27: 0.87048434 | F27: 0.12951566 | P27: =ROUND(O27*E27,-3) -> - | Q27: =ROUND(O27*F27,-3) -> - | R27: =ROUND(P27*0.1,-3) -> - | S27: =SUM(P27:R27) -> - | AK27: 307
A28: 20 | D28: 308 | E28: 0.87046411 | F28: 0.12953589 | P28: =ROUND(O28*E28,-3) -> - | Q28: =ROUND(O28*F28,-3) -> - | R28: =ROUND(P28*0.1,-3) -> - | S28: =SUM(P28:R28) -> - | AK28: 308
D29: 소계 | G29: 164.47832 | H29: 287.63212 | I29: 2919700000 | N29: =SUM(N21:N28) -> 3,173,856,000 | O29: =SUM(O21:O28) -> 0 | S29: =SUM(S21:S28) -> - | T29: =SUM(T21:T28) -> 2,475,607,680 | U29: =SUM(U21:U28) -> 698,248,320 | AA29: =SUM(AA21:AA28) -> 0 | AD29: =SUM(AD21:AD28) -> 0 | AF29: =SUM(AF21:AF28) -> 0 | AG29: =SUM(AG21:AG28) -> 2,475,607,680 | AH29: =SUM(AH21:AH28) -> - | AS29: =SUM(AS21:AS23) -> 0 | AT29: =SUM(AT21:AT23) -> 0 | AZ29: =SUM(AZ21:AZ28) -> 179,962,211
A30: 21 | D30: 401 | E30: 0.87006142 | F30: 0.12993858 | G30: 43.45 | H30: 75.15 | I30: 388000000 | J30: =ROUND(I30*E30,-3) -> 337,584,000 | K30: =ROUND(I30*F30,-3) -> 50,416,000 | L30: =ROUND(J30*10%,-3) -> 33,758,000 | M30: =SUM(J30:L30) -> 421,758,000 | N30: =(M30)+M31 -> 844,059,000 | P30: =ROUND(O30*E30,-3) -> - | Q30: =ROUND(O30*F30,-3) -> - | R30: =ROUND(P30*0.1,-3) -> - | S30: =SUM(P30:R30) -> - | T30: =N30*(1-0.22) -> 658,366,020 | U30: =N30-T30 -> 185,692,980 | V30: =U30/N30 -> 22% | Z30: 45790 | AA30: 84405900 | AB30: =AA30/N30 -> 10% | AC30: 45820 | AD30: =AA30 -> 84,405,900 | AE30: 45850 | AF30: 675247200 | AG30: =AF30+AD30 -> 759,653,100 | AH30: =AA30+AF30 -> 759,653,100 | AI30: 45483 | AK30: 401 | AL30: 선임대 | AM30: 민경준 | AO30: 태권도 | AP30: 2024.07.10-2026.07.10 | AQ30: 46213 | AR30: =(AQ30-TODAY()) -> 53일 | AS30: 40000000 | AT30: =1750000*2 -> 3,500,000 | AU30: =AT30*12/(N30-AS30) -> 5.22% | AV30: =AT30*12/(T30-AS30) -> 6.79% | AW30: 매월 2일(선불) | AX30: 0 | AZ30: =(T30-N30*65%)*1.1 -> 120,700,437 | BA30: =AZ30-BB30 -> 99,250,437 | BB30: =(AS30+(AT30*100))*5%*1.1 -> 21,450,000
E31: 0.87004637 | F31: 0.12995363 | I31: 388500000 | J31: =ROUND(I31*E31,-3) -> 338,013,000 | K31: =ROUND(I31*F31,-3) -> 50,487,000 | L31: =ROUND(J31*10%,-3) -> 33,801,000 | M31: =SUM(J31:L31) -> 422,301,000 | P31: =ROUND(O31*E31,-3) -> - | Q31: =ROUND(O31*F31,-3) -> - | R31: =ROUND(P31*0.1,-3) -> - | S31: =SUM(P31:R31) -> -
A32: 22 | D32: 402 | E32: 0.87008361 | F32: 0.12991639 | G32: 21.534975 | H32: 37.519075 | I32: 368900000 | J32: =ROUND(I32*E32,-3) -> 320,974,000 | K32: =ROUND(I32*F32,-3) -> 47,926,000 | L32: =ROUND(J32*10%,-3) -> 32,097,000 | M32: =SUM(J32:L32) -> 400,997,000 | N32: =(M32) -> 400,997,000 | P32: =ROUND(O32*E32,-3) -> - | Q32: =ROUND(O32*F32,-3) -> - | R32: =ROUND(P32*0.1,-3) -> - | S32: =SUM(P32:R32) -> - | T32: =N32*(1-0.3) -> 280,697,900 | U32: =N32-T32 -> 120,299,100 | V32: =U32/N32 -> 30% | Z32: 45790 | AA32: 40099700 | AB32: =AA32/N32 -> 10% | AC32: 45820 | AD32: =AA32 -> 40,099,700 | AE32: 45850 | AF32: 320797600 | AG32: =AF32+AD32 -> 360,897,300 | AH32: =AA32+AF32 -> 360,897,300 | AK32: 402 | AZ32: =(T32-(N32*65%))*1.1 -> 22,054,835 | BA32: =AZ32-BB32 -> 22,054,835 | BB32: =(AS32+(AT32*100))*5%*1.1 -> -
A33: 23 | D33: 403 | E33: 0.87005151 | F33: 0.12994849 | G33: 21.97965 | H33: 38.29045 | I33: 376700000 | J33: =ROUND(I33*E33,-3) -> 327,748,000 | K33: =ROUND(I33*F33,-3) -> 48,952,000 | L33: =ROUND(J33*10%,-3) -> 32,775,000 | M33: =SUM(J33:L33) -> 409,475,000 | N33: =(M33) -> 409,475,000 | P33: =ROUND(O33*E33,-3) -> - | Q33: =ROUND(O33*F33,-3) -> - | R33: =ROUND(P33*0.1,-3) -> - | S33: =SUM(P33:R33) -> - | T33: =N33*(1-0.22) -> 319,390,500 | U33: =N33-T33 -> 90,084,500 | V33: =U33/N33 -> 22% | Z33: 45790 | AA33: 40947500 | AB33: =AA33/N33 -> 10% | AC33: 45820 | AD33: =AA33 -> 40,947,500 | AE33: 45850 | AF33: 327580000 | AG33: =AF33+AD33 -> 368,527,500 | AH33: =AA33+AF33 -> 368,527,500 | AK33: 403 | AZ33: =(T33-(N33*65%))*1.1 -> 58,554,925 | BA33: =AZ33-BB33 -> 58,554,925 | BB33: =(AS33+(AT33*100))*5%*1.1 -> -
A34: 24 | D34: 404 | E34: 0.87005151 | F34: 0.12994849 | G34: 21.97965 | H34: 38.29045 | I34: 376700000 | J34: =ROUND(I34*E34,-3) -> 327,748,000 | K34: =ROUND(I34*F34,-3) -> 48,952,000 | L34: =ROUND(J34*10%,-3) -> 32,775,000 | M34: =SUM(J34:L34) -> 409,475,000 | N34: =(M34) -> 409,475,000 | P34: =ROUND(O34*E34,-3) -> - | Q34: =ROUND(O34*F34,-3) -> - | R34: =ROUND(P34*0.1,-3) -> - | S34: =SUM(P34:R34) -> - | T34: =N34*(1-0.22) -> 319,390,500 | U34: =N34-T34 -> 90,084,500 | V34: =U34/N34 -> 22% | Z34: 45790 | AA34: 40947500 | AB34: =AA34/N34 -> 10% | AC34: 45820 | AD34: =AA34 -> 40,947,500 | AE34: 45850 | AF34: 327580000 | AG34: =AF34+AD34 -> 368,527,500 | AH34: =AA34+AF34 -> 368,527,500 | AK34: 404 | AZ34: =(T34-(N34*65%))*1.1 -> 58,554,925 | BA34: =AZ34-BB34 -> 58,554,925 | BB34: =(AS34+(AT34*100))*5%*1.1 -> -
A35: 25 | D35: 405 | E35: 0.87005151 | F35: 0.12994849 | G35: 21.97965 | H35: 38.29045 | I35: 393200000 | J35: =ROUND(I35*E35,-3) -> 342,104,000 | K35: =ROUND(I35*F35,-3) -> 51,096,000 | L35: =ROUND(J35*10%,-3) -> 34,210,000 | M35: =SUM(J35:L35) -> 427,410,000 | N35: =(M35) -> 427,410,000 | P35: =ROUND(O35*E35,-3) -> - | Q35: =ROUND(O35*F35,-3) -> - | R35: =ROUND(P35*0.1,-3) -> - | S35: =SUM(P35:R35) -> - | T35: =N35*(1-0.22) -> 333,379,800 | U35: =N35-T35 -> 94,030,200 | V35: =U35/N35 -> 22% | Z35: 45790 | AA35: =N35*0.1 -> 42,741,000 | AB35: =AA35/N35 -> 10% | AC35: 45820 | AD35: =AA35 -> 42,741,000 | AE35: 45850 | AF35: 341928000 | AG35: =AF35+AD35 -> 384,669,000 | AH35: =AA35+AF35 -> 384,669,000 | AK35: 405 | AZ35: =(T35-(N35*65%))*1.1 -> 61,119,630 | BA35: =AZ35-BB35 -> 61,119,630 | BB35: =(AS35+(AT35*100))*5%*1.1 -> -
A36: 26 | D36: 406 | E36: 0.8701419 | F36: 0.1298581 | G36: 28.7012 | H36: 50.157525 | I36: 540500000 | J36: =ROUND(I36*E36,-3) -> 470,312,000 | K36: =ROUND(I36*F36,-3) -> 70,188,000 | L36: =ROUND(J36*10%,-3) -> 47,031,000 | M36: =SUM(J36:L36) -> 587,531,000 | N36: =(M36) -> 587,531,000 | P36: =ROUND(O36*E36,-3) -> - | Q36: =ROUND(O36*F36,-3) -> - | R36: =ROUND(P36*0.1,-3) -> - | S36: =SUM(P36:R36) -> - | T36: =N36*(1-0.22) -> 458,274,180 | U36: =N36-T36 -> 129,256,820 | V36: =U36/N36 -> 22% | Z36: 45790 | AA36: =N36*0.1 -> 58,753,100 | AB36: =AA36/N36 -> 10% | AC36: 45820 | AD36: =AA36 -> 58,753,100 | AE36: 45850 | AF36: 470024800 | AG36: =AF36+AD36 -> 528,777,900 | AH36: =AA36+AF36 -> 528,777,900 | AK36: 406 | AZ36: =(T36-(N36*65%))*1.1 -> 84,016,933 | BA36: =AZ36-BB36 -> 84,016,933 | BB36: =(AS36+(AT36*100))*5%*1.1 -> -
D37: 소계 | G37: 158.76107 | H37: 276.73608 | I37: 2832500000 | N37: =SUM(N30:N36) -> 3,078,947,000 | O37: =SUM(O30:O36) -> 0 | S37: =SUM(S30:S36) -> - | T37: =SUM(T30:T36) -> 2,369,498,900 | U37: =SUM(U30:U36) -> 709,448,100 | AA37: =SUM(AA30:AA36) -> 307,894,700 | AD37: =SUM(AD30:AD36) -> 307,894,700 | AF37: =SUM(AF30:AF36) -> 2,463,157,600 | AG37: =SUM(AG30:AG36) -> 2,771,052,300 | AH37: =SUM(AH30:AH36) -> 2,771,052,300 | AS37: =SUM(AS30:AS36) -> 40,000,000 | AT37: =SUM(AT30:AT36) -> 3,500,000 | AZ37: =SUM(AZ30:AZ36) -> 405,001,685
A38: =COUNTA(A7:A12,A14:A19,A21:A28,A30:A36) -> 전체 합계(26호실) | N38: =N13+N20+N29+N37 -> 11,631,323,000 | O38: =O37+O29+O20+O59 -> 0 | T38: =T37+T29+T20+T59 -> 7,240,956,040 | AA38: =AA13+AA20+AA29+AA37 -> 307,894,700 | AD38: =AD13+AD20+AD29+AD37 -> 307,894,700 | AF38: =AF13+AF20+AF29+AF37 -> 2,463,157,600 | AM38: 임대 합계 | AO38: =COUNTA(AK7:AK37) -> 시행사보유분 전체합계 (26개 호실) | AS38: =SUM(AS37,AS29,AS20,AS13) -> 145,000,000 | AT38: =SUM(AT37,AT29,AT20,AT13) -> 9,100,000 | AW38: 미수임대료 | AX38: =SUM(AX30:AX36,AX21:AX23,AX14:AX19,AX7:AX12) -> 0 | AY38: 수수료 총합 | AZ38: =SUM(AZ37,AZ29,AZ20,AZ13) -> 1,354,092,256
A39: =COUNTIF(B7:B37,"=분양") -> 분양 합계(0호실) | N39: =SUMIF($B$7:$B$37,"=분양",N7:N37) -> - | T39: =SUMIF($B$7:$B$37,"=분양",T7:T37) -> - | AA39: =SUMIF($B$7:$B$37,"=분양",AA7:AA37) -> - | AD39: =SUMIF($B$7:$B$37,"=분양",AD7:AD37) -> - | AO39: =COUNTIF(AL7:AL37,"선임대") -> 시행사보유분 확정합계 (5개 호실) | AS39: =SUMIF($AL7:AL29,"선임대",AS7:AS23)+SUMIF($AL30:AL37,"선임대",AS30:AS37) -> 145,000,000 | AT39: =SUMIF($AL7:AM29,"선임대",AT7:AT23)+SUMIF($AL30:AM37,"선임대",AT30:AT37) -> 9,100,000 | AX39: =AX38='[1]향남근생 월세수금'!O13 -> #REF!
A40: =A38-A39 -> 미분양 합계(26호실) | N40: =N38-N39 -> 11,631,323,000 | T40: =T38-T39 -> 7,240,956,040 | AA40: =AA38-AA39 -> 307,894,700 | AD40: =AD38-AD39 -> 307,894,700 | AF40: =AF38-AF39 -> 2,463,157,600 | AO40: =AO38-AO39 -> 시행사보유분 예정합계 (21개 호실) | AS40: =AS38-AS39 -> - | AT40: =AT38-AT39 -> -
E43: =SUM(E24:E28) -> 435.2412% | F43: =SUM(F24:F28) -> 64.7588% | H43: =SUM(H24:H28) -> 175.5
...

Sheet 향남 단독부지
A1: 향남역 단독, 상가주택부지
A4: 상세현황
A5: 구분 | B5: 순번 | C5: 위치 | D5: BL | E5: 면적(㎡) | F5: 면적(평) | G5: 2025년 공시지가 | H5: 분양 예정가 | K5: 원가 계산 | P5: 영업 현황
H6: 분양가 | I6: 분양대행사 수수료(정찰제) | J6: 평당분양가 | K6: 장부가액 | L6: 금융비용 | M6: 도시계획시설 +대지조성공사 | N6: 총취득원가 | O6: 평당취득가
A7: 단독주택부지 | B7: 1 | C7: 상신리 664-1 일원 | D7: C1-1 | E7: 249 | F7: =E7/3.3058 -> 75.32평 | G7: =384800*E7 -> 95,815,200 | H7: =F7*J7 -> 414,271,886 | I7: 75320000 | J7: 5500000 | K7: 158634947 | L7: 25648292 | M7: 17792034 | N7: =SUM(K7:M7) -> 202,075,273 | O7: =+ROUND(N7/F7,0) -> 2,682,813
B8: 2 | C8: 상신리 664-1 일원 | D8: C1-2 | E8: 227 | F8: =E8/3.3058 -> 68.67평 | G8: =384800*E8 -> 87,349,600 | H8: =F8*J8 -> 377,669,550 | I8: 68670000 | J8: 5500000 | K8: 145944151 | L8: 23596428 | M8: 16368671 | N8: =SUM(K8:M8) -> 185,909,250 | O8: =+ROUND(N8/F8,0) -> 2,707,396
B9: 3 | C9: 상신리 664-1 일원 | D9: C1-3 | E9: 234 | F9: =E9/3.3058 -> 70.78평 | G9: =384800*E9 -> 90,043,200 | H9: =F9*J9 -> 389,315,748 | I9: 70780000 | J9: 5500000 | K9: 150174416 | L9: 24280383 | M9: 16843125 | N9: =SUM(K9:M9) -> 191,297,924 | O9: =+ROUND(N9/F9,0) -> 2,702,533
B10: 4 | C10: 상신리 664-1 일원 | D10: C1-4 | E10: 238 | F10: =E10/3.3058 -> 71.99평 | G10: =384800*E10 -> 91,582,400 | H10: =F10*J10 -> 395,970,718 | I10: 71990000 | J10: 5500000 | K10: 152289549 | L10: 24622360 | M10: 17080352 | N10: =SUM(K10:M10) -> 193,992,261 | O10: =+ROUND(N10/F10,0) -> 2,694,536
B11: 5 | C11: 상신리 665-59 일원 | D11: C1-5 | E11: 243 | F11: =E11/3.3058 -> 73.51평 | G11: =439300*E11 -> 106,749,900 | H11: =F11*J11 -> 404,289,431 | I11: 73510000 | J11: 5500000 | K11: 156519814 | L11: 25306314 | M11: 17554806 | N11: =SUM(K11:M11) -> 199,380,934 | O11: =+ROUND(N11/F11,0) -> 2,712,401
B12: 6 | C12: 상신리 665-59 일원 | D12: C1-6 | E12: 240 | F12: =E12/3.3058 -> 72.6평 | G12: =439300*E12 -> 105,432,000 | H12: =F12*J12 -> 399,298,203 | I12: 72600000 | J12: 5500000 | K12: 154404681 | L12: 24964337 | M12: 17317579 | N12: =SUM(K12:M12) -> 196,686,597 | O12: =+ROUND(N12/F12,0) -> 2,709,194
B13: 7 | C13: 상신리 665-59 일원 | D13: C1-7 | E13: 232 | F13: =E13/3.3058 -> 70.18평 | G13: =439300*E13 -> 101,917,600 | H13: =F13*J13 -> 385,988,263 | I13: 70180000 | J13: 5500000 | K13: 148059284 | L13: 23938406 | M13: 16605898 | N13: =SUM(K13:M13) -> 188,603,588 | O13: =+ROUND(N13/F13,0) -> 2,687,439
B14: 소계 | E14: =SUM(E7:E13) -> 1,663.㎡ | F14: =SUM(F7:F13) -> 503.06평 | G14: =SUM(G7:G13) -> 678,889,900 | H14: =SUM(H7:H13) -> 2,766,803,799 | I14: =SUM(I7:I13) -> 503,050,000 | K14: =SUM(K7:K13) -> 1,066,026,842 | L14: =SUM(L7:L13) -> 172,356,520 | M14: =SUM(M7:M13) -> 119,562,465 | N14: =SUM(N7:N13) -> 1,357,945,827 | O14: =SUM(O7:O13) -> 18,896,312
A15: 상가주택부지 | B15: 8 | C15: 상신리 663-10 일원 | D15: C1-8 | E15: 266 | F15: =E15/3.3058 -> 80.46평 | G15: =182300*E15 -> 48,491,800 | H15: =F15*J15 -> 482,787,827 | I15: 80460000 | J15: 6000000 | K15: 169210610 | L15: 27358178 | M15: 18978169 | N15: =SUM(K15:M15) -> 215,546,957 | O15: =+ROUND(N15/F15,0) -> 2,678,779
B16: 9 | C16: 상신리 663-10 일원 | D16: C1-9 | E16: 245 | F16: =E16/3.3058 -> 74.11평 | G16: =182300*E16 -> 44,663,500 | H16: =F16*J16 -> 444,672,999 | I16: 74110000 | J16: 6000000 | K16: 156519814 | L16: 25306314 | M16: 17554806 | N16: =SUM(K16:M16) -> 199,380,934 | O16: =+ROUND(N16/F16,0) -> 2,690,259
B17: 10 | C17: 상신리 663-10 일원 | D17: C1-10 | E17: 249 | F17: =E17/3.3058 -> 75.32평 | G17: =182300*E17 -> 45,392,700 | H17: =F17*J17 -> 451,932,966 | I17: 75320000 | J17: 6000000 | K17: 158634947 | L17: 25648292 | M17: 17792034 | N17: =SUM(K17:M17) -> 202,075,273 | O17: =+ROUND(N17/F17,0) -> 2,682,813
